Workbook
Name Ambrose: Players!$J$3:$J$14
Name HC16_Skins: Players!$N$3:$N$47
Name HC15_FRI: Players!$N$3:$N$51
Name Player_List: #REF!
Name HC15_SAT: Players!$C$3:$C$68
Name COURSES: Players!$F$3:$F$5
Name Players1: Players!$C$3:$C$68
Name HC16_Sat: Players!$C$3:$C$68
Name PLAYER: Players!$C$2:$C$68
Name HC16_Ambrose: Players!$J$3:$J$15
Name HC18_Ambrose: Players!$J$3:$J$22
Name TP: Players!$N$3:$N$55
Name HC17_Sat: Players!$C$3:$C$68
Name HC17_Fri: Players!$N$3:$N$51
Name Player_List: #REF!
Name HC15_SUN: Players!$J$3:$J$14
Name COURSES: Players!$F$3:$F$5
Name HC17_Sun: Players!$J$3:$J$14

Sheet Database
A1: Name | B1: Handicap
A2: Brendan Oakes | B2: 20
A3: Andrew Murray | B3: 20
A4: Noel Jago | B4: 29
A5: Peter Keen | B5: 29 | C5: 8 | D5: 6 | E5: 7 | F5: 6 | G5: 9 | H5: 9 | I5: 8 | J5: 5 | K5: 7 | L5: 5 | M5: 6 | N5: 5 | O5: 6 | P5: 6 | Q5: 5 | R5: 6 | S5: 4 | T5: 6
A6: Martyn Budden | B6: 12
A7: Ashley Oakes | B7: 29
A8: Matt Jackson | B8: 31
A9: Phil Carney | B9: 17
A10: Chris Chilcott | B10: 25
A11: Damien Starcic | B11: 30
A12: Daniel Graham | B12: 23
A13: Adam Paton | B13: 7
A14: Matt Rowan | B14: 29
A15: Steve Press | B15: 18
A16: Steve Walters | B16: 18
A17: Darryn Rooks | B17: 20
... A50: Joel Shepherd | B50: 22
A51: Glenn Hickey | B51: 27 | C51: 7 | D51: 5 | E51: 6 | F51: 9 | G51: 7 | H51: 3 | I51: 7 | J51: 6 | K51: 8 | L51: 5 | M51: 5 | N51: 6 | O51: 3 | P51: 6 | Q51: 6 | R51: 6 | S51: 9 | T51: 4
A52: Jordan Whitehorn | B52: 22
A53: Greg Gomes | B53: 22
A54: Ben Wood | B54: 7
A55: Sam Edwards | B55: 26
A56: Derek Shepherd | B56: 22
A57: Matthew Toohey | B57: 20
A58: Edward OSullivan | B58: 22
A59: Andrew Minnikin | B59: 22
A60: Paul Zepernick | B60: 3
A61: Brad Spurway | B61: 3
A62: Willie Cooper | B62: 32
A63: Joe Foia | B63: 26
... A68: Nick Williams | B68: 27

Sheet Sheet10

Sheet Sheet9

Sheet Sheet4

Sheet Sheet5

Sheet Sheet6

Sheet Sheet7

Sheet Sheet1

Sheet Course Info
B2: COURSE | C2: HOLE | D2: PAR | E2: INDEX 1 | F2: INDEX 2 | G2: DIST (m)
B3: Worrigee | C3: 1 | D3: 5 | E3: 10 | F3: 23 | G3: 473
B4: Worrigee | C4: 2 | D4: 3 | E4: 1 | F4: 26 | G4: 210
B5: Worrigee | C5: 3 | D5: 4 | E5: 12 | F5: 29 | G5: 330
B6: Worrigee | C6: 4 | D6: 4 | E6: 16 | F6: 32 | G6: 292
B7: Worrigee | C7: 5 | D7: 4 | E7: 3 | F7: 21 | G7: 360
B8: Worrigee | C8: 6 | D8: 3 | E8: 15 | F8: 36 | G8: 165
B9: Worrigee | C9: 7 | D9: 5 | E9: 6 | F9: 19 | G9: 497
B10: Worrigee | C10: 8 | D10: 3 | E10: 8 | F10: 31 | G10: 160
B11: Worrigee | C11: 9 | D11: 4 | E11: 4 | F11: 20 | G11: 350
B12: Worrigee | C12: 10 | D12: 4 | E12: 7 | F12: 22 | G12: 335
B13: Worrigee | C13: 11 | D13: 5 | E13: 11 | F13: 30 | G13: 444
B14: Worrigee | C14: 12 | D14: 3 | E14: 2 | F14: 27 | G14: 185
... B20: Worrigee | C20: 18 | D20: 5 | E20: 14 | F20: 28 | G20: 445

Sheet Sheet3

Sheet Players
B2: NUMBER | C2: PLAYER | D2: HANDICAP | F2: COURSES | G2: NUMBER | H2: PLAYER 1 | I2: PLAYER 2 | J2: AMBROSE | K2: HANDICAP | M2: NUMBER | N2: TP SKINS | O2: HANDICAP
B3: 1 | C3: =Database!A2 -> Brendan Oakes | D3: =VLOOKUP($C3,Database!$A:$B,2,0) -> 20 | F3: CAMDEN HAVEN | G3: 1 | H3: Andrew Murray | I3: Brendan Oakes | J3: =H3&" - "&I3 -> Andrew Murray - Brendan Oakes | K3: =(VLOOKUP(H3,$C:$D,2,0)+VLOOKUP(I3,$C:$D,2,0))/4 -> 10 | M3: 1 | N3: Brendan Oakes | O3: =VLOOKUP($N3,Database!$A:$B,2,0) -> 20
B4: =B3+1 -> 2 | C4: =Database!A3 -> Andrew Murray | D4: =VLOOKUP($C4,Database!$A:$B,2,0) -> 20 | F4: EMERALD DOWNS | G4: =G3+1 -> 2 | H4: Phil Carney | I4: Steve Walters | J4: =H4&" - "&I4 -> Phil Carney - Steve Walters | K4: =(VLOOKUP(H4,$C:$D,2,0)+VLOOKUP(I4,$C:$D,2,0))/4 -> 8.75 | M4: =M3+1 -> 2 | N4: Andrew Murray | O4: =VLOOKUP($N4,Database!$A:$B,2,0) -> 20
B5: =B4+1 -> 3 | C5: =Database!A4 -> Noel Jago | D5: =VLOOKUP($C5,Database!$A:$B,2,0) -> 29 | F5: WAUCHOPE | G5: =G4+1 -> 3 | H5: David Simpson | I5: Steve Press | J5: =H5&" - "&I5 -> David Simpson - Steve Press | K5: =(VLOOKUP(H5,$C:$D,2,0)+VLOOKUP(I5,$C:$D,2,0))/4 -> 8.5 | M5: =M4+1 -> 3 | N5: Noel Jago | O5: =VLOOKUP($N5,Database!$A:$B,2,0) -> 29
B6: =B5+1 -> 4 | C6: =Database!A5 -> Peter Keen | D6: =VLOOKUP($C6,Database!$A:$B,2,0) -> 29 | G6: =G5+1 -> 4 | H6: Noel Jago | I6: Mark Leaney | J6: =H6&" - "&I6 -> Noel Jago - Mark Leaney | K6: =(VLOOKUP(H6,$C:$D,2,0)+VLOOKUP(I6,$C:$D,2,0))/4 -> 14.25 | M6: =M5+1 -> 4 | N6: Martyn Budden | O6: =VLOOKUP($N6,Database!$A:$B,2,0) -> 12
B7: =B6+1 -> 5 | C7: =Database!A6 -> Martyn Budden | D7: =VLOOKUP($C7,Database!$A:$B,2,0) -> 12 | G7: =G6+1 -> 5 | H7: Justinn Curan | I7: Anker Christensen | J7: =H7&" - "&I7 -> Justinn Curan - Anker Christensen | K7: =(VLOOKUP(H7,$C:$D,2,0)+VLOOKUP(I7,$C:$D,2,0))/4 -> 15.25 | M7: =M6+1 -> 5 | N7: Ashley Oakes | O7: =VLOOKUP($N7,Database!$A:$B,2,0) -> 29
B8: =B7+1 -> 6 | C8: =Database!A7 -> Ashley Oakes | D8: =VLOOKUP($C8,Database!$A:$B,2,0) -> 29 | G8: =G7+1 -> 6 | H8: Brad Rogers | I8: Glenn Palmer | J8: =H8&" - "&I8 -> Brad Rogers - Glenn Palmer | K8: =(VLOOKUP(H8,$C:$D,2,0)+VLOOKUP(I8,$C:$D,2,0))/4 -> 2.25 | M8: =M7+1 -> 6 | N8: Matt Jackson | O8: =VLOOKUP($N8,Database!$A:$B,2,0) -> 31
B9: =B8+1 -> 7 | C9: =Database!A8 -> Matt Jackson | D9: =VLOOKUP($C9,Database!$A:$B,2,0) -> 31 | G9: =G8+1 -> 7 | H9: Brad Grant | I9: Jeff Hawkins | J9: =H9&" - "&I9 -> Brad Grant - Jeff Hawkins | K9: =(VLOOKUP(H9,$C:$D,2,0)+VLOOKUP(I9,$C:$D,2,0))/4 -> 13.5 | M9: =M8+1 -> 7 | N9: Phil Carney | O9: =VLOOKUP($N9,Database!$A:$B,2,0) -> 17
B10: =B9+1 -> 8 | C10: =Database!A9 -> Phil Carney | D10: =VLOOKUP($C10,Database!$A:$B,2,0) -> 17 | G10: =G9+1 -> 8 | H10: Josh Fryer | I10: Scott Austin | J10: =H10&" - "&I10 -> Josh Fryer - Scott Austin | K10: =(VLOOKUP(H10,$C:$D,2,0)+VLOOKUP(I10,$C:$D,2,0))/4 -> 8 | M10: =M9+1 -> 8 | N10: Chris Chilcott | O10: =VLOOKUP($N10,Database!$A:$B,2,0) -> 25
B11: =B10+1 -> 9 | C11: =Database!A10 -> Chris Chilcott | D11: =VLOOKUP($C11,Database!$A:$B,2,0) -> 25 | G11: =G10+1 -> 9 | H11: Ashley Oakes | I11: Chris Chilcott | J11: =H11&" - "&I11 -> Ashley Oakes - Chris Chilcott | K11: =(VLOOKUP(H11,$C:$D,2,0)+VLOOKUP(I11,$C:$D,2,0))/4 -> 13.5 | M11: =M10+1 -> 9 | N11: Damien Starcic | O11: =VLOOKUP($N11,Database!$A:$B,2,0) -> 30
B12: =B11+1 -> 10 | C12: =Database!A11 -> Damien Starcic | D12: =VLOOKUP($C12,Database!$A:$B,2,0) -> 30 | G12: =G11+1 -> 10 | H12: Mark Lever | I12: Antony Seel | J12: =H12&" - "&I12 -> Mark Lever - Antony Seel | K12: =(VLOOKUP(H12,$C:$D,2,0)+VLOOKUP(I12,$C:$D,2,0))/4 -> 11.25 | M12: =M11+1 -> 10 | N12: Daniel Graham | O12: =VLOOKUP($N12,Database!$A:$B,2,0) -> 23
B13: =B12+1 -> 11 | C13: =Database!A12 -> Daniel Graham | D13: =VLOOKUP($C13,Database!$A:$B,2,0) -> 23 | G13: =G12+1 -> 11 | H13: Glenn Clay | I13: Neil Watson | J13: =H13&" - "&I13 -> Glenn Clay - Neil Watson | K13: =(VLOOKUP(H13,$C:$D,2,0)+VLOOKUP(I13,$C:$D,2,0))/4 -> 14.5 | M13: =M12+1 -> 11 | N13: Adam Paton | O13: =VLOOKUP($N13,Database!$A:$B,2,0) -> 7
B14: =B13+1 -> 12 | C14: =Database!A13 -> Adam Paton | D14: =VLOOKUP($C14,Database!$A:$B,2,0) -> 7 | G14: =G13+1 -> 12 | H14: Peter Keen | I14: Glenn Hickey | J14: =H14&" - "&I14 -> Peter Keen - Glenn Hickey | K14: =(VLOOKUP(H14,$C:$D,2,0)+VLOOKUP(I14,$C:$D,2,0))/4 -> 14 | M14: =M13+1 -> 12 | N14: Matt Rowan | O14: =VLOOKUP($N14,Database!$A:$B,2,0) -> 29
B15: =B14+1 -> 13 | C15: =Database!A14 -> Matt Rowan | D15: =VLOOKUP($C15,Database!$A:$B,2,0) -> 29 | G15: =G14+1 -> 13 | H15: Joe Pajeska | I15: Matt Rowan | J15: =H15&" - "&I15 -> Joe Pajeska - Matt Rowan | K15: =(VLOOKUP(H15,$C:$D,2,0)+VLOOKUP(I15,$C:$D,2,0))/4 -> 15 | M15: =M14+1 -> 13 | N15: Steve Press | O15: =VLOOKUP($N15,Database!$A:$B,2,0) -> 18
B16: =B15+1 -> 14 | C16: =Database!A15 -> Steve Press | D16: =VLOOKUP($C16,Database!$A:$B,2,0) -> 18 | G16: =G15+1 -> 14 | H16: Matthew Zibert | I16: Ernie Zibert | J16: =H16&" - "&I16 -> Matthew Zibert - Ernie Zibert | K16: =(VLOOKUP(H16,$C:$D,2,0)+VLOOKUP(I16,$C:$D,2,0))/4 -> 5.5 | M16: =M15+1 -> 14 | N16: Steve Walters | O16: =VLOOKUP($N16,Database!$A:$B,2,0) -> 18
B17: =B16+1 -> 15 | C17: =Database!A16 -> Steve Walters | D17: =VLOOKUP($C17,Database!$A:$B,2,0) -> 18 | G17: =G16+1 -> 15 | H17: Damien Starcic | I17: Warren Gibson | J17: =H17&" - "&I17 -> Damien Starcic - Warren Gibson | K17: =(VLOOKUP(H17,$C:$D,2,0)+VLOOKUP(I17,$C:$D,2,0))/4 -> 10 | M17: =M16+1 -> 15 | N17: Darryn Rooks | O17: =VLOOKUP($N17,Database!$A:$B,2,0) -> 20
... B35: =B34+1 -> 33 | C35: =Database!A34 -> Justinn Curan | D35: =VLOOKUP($C35,Database!$A:$B,2,0) -> 31 | G35: =G34+1 -> 33 | H35: Paul Murray | I35: Dan Sullivan | J35: =H35&" - "&I35 -> Paul Murray - Dan Sullivan | K35: =(VLOOKUP(H35,$C:$D,2,0)+VLOOKUP(I35,$C:$D,2,0))/4 -> 7.5 | M35: =M34+1 -> 33 | N35: Antony Seel | O35: =VLOOKUP($N35,Database!$A:$B,2,0) -> 21
B36: =B35+1 -> 34 | C36: =Database!A35 -> Antony Seel | D36: =VLOOKUP($C36,Database!$A:$B,2,0) -> 21 | M36: =M35+1 -> 34 | N36: Jeff Hawkins | O36: =VLOOKUP($N36,Database!$A:$B,2,0) -> 27
B37: =B36+1 -> 35 | C37: =Database!A36 -> Glenn Clay | D37: =VLOOKUP($C37,Database!$A:$B,2,0) -> 31 | M37: =M36+1 -> 35 | N37: David Simpson | O37: =VLOOKUP($N37,Database!$A:$B,2,0) -> 16
B38: =B37+1 -> 36 | C38: =Database!A37 -> Neil Watson | D38: =VLOOKUP($C38,Database!$A:$B,2,0) -> 27 | M38: =M37+1 -> 36 | N38: Grant Pelley | O38: =VLOOKUP($N38,Database!$A:$B,2,0) -> 27
B39: =B38+1 -> 37 | C39: =Database!A38 -> Jeff Hawkins | D39: =VLOOKUP($C39,Database!$A:$B,2,0) -> 27 | M39: =M38+1 -> 37 | N39: Anker Christensen | O39: =VLOOKUP($N39,Database!$A:$B,2,0) -> 30
B40: =B39+1 -> 38 | C40: =Database!A39 -> David Simpson | D40: =VLOOKUP($C40,Database!$A:$B,2,0) -> 16 | M40: =M39+1 -> 38 | N40: Mark Anderson | O40: =VLOOKUP($N40,Database!$A:$B,2,0) -> 31
B41: =B40+1 -> 39 | C41: =Database!A40 -> Grant Pelley | D41: =VLOOKUP($C41,Database!$A:$B,2,0) -> 27 | M41: =M40+1 -> 39 | N41: Glen Duley | O41: =VLOOKUP($N41,Database!$A:$B,2,0) -> 25
B42: =B41+1 -> 40 | C42: =Database!A41 -> Anker Christensen | D42: =VLOOKUP($C42,Database!$A:$B,2,0) -> 30 | M42: =M41+1 -> 40 | N42: Michael Lagudi | O42: =VLOOKUP($N42,Database!$A:$B,2,0) -> 8
B43: =B42+1 -> 41 | C43: =Database!A42 -> Dan Sullivan | D43: =VLOOKUP($C43,Database!$A:$B,2,0) -> 8 | M43: =M42+1 -> 41 | N43: Riley Oakes | O43: =VLOOKUP($N43,Database!$A:$B,2,0) -> 22
B44: =B43+1 -> 42 | C44: =Database!A43 -> Matthew Zibert | D44: =VLOOKUP($C44,Database!$A:$B,2,0) -> 6 | M44: =M43+1 -> 42 | N44: Joel Shepherd | O44: =VLOOKUP($N44,Database!$A:$B,2,0) -> 22
B45: =B44+1 -> 43 | C45: =Database!A44 -> Mark Anderson | D45: =VLOOKUP($C45,Database!$A:$B,2,0) -> 31 | M45: =M44+1 -> 43 | N45: Jordan Whitehorn | O45: =VLOOKUP($N45,Database!$A:$B,2,0) -> 22
B46: =B45+1 -> 44 | C46: =Database!A45 -> Glen Duley | D46: =VLOOKUP($C46,Database!$A:$B,2,0) -> 25 | M46: =M45+1 -> 44 | N46: Greg Gomes | O46: =VLOOKUP($N46,Database!$A:$B,2,0) -> 22
B47: =B46+1 -> 45 | C47: =Database!A46 -> Ed Howitt | D47: =VLOOKUP($C47,Database!$A:$B,2,0) -> 30 | M47: =M46+1 -> 45 | N47: Ben Wood | O47: =VLOOKUP($N47,Database!$A:$B,2,0) -> 7
... B61: =B60+1 -> 59 | C61: =Database!A60 -> Paul Zepernick | D61: =VLOOKUP($C61,Database!$A:$B,2,0) -> 3 | M61: =M60+1 -> 59 | N61: Nick Williams | O61: =VLOOKUP($N61,Database!$A:$B,2,0) -> 27
B62: =B61+1 -> 60 | C62: =Database!A61 -> Brad Spurway | D62: =VLOOKUP($C62,Database!$A:$B,2,0) -> 3
B63: =B62+1 -> 61 | C63: =Database!A62 -> Willie Cooper | D63: =VLOOKUP($C63,Database!$A:$B,2,0) -> 32
B64: =B63+1 -> 62 | C64: =Database!A63 -> Joe Foia | D64: =VLOOKUP($C64,Database!$A:$B,2,0) -> 26
B65: =B64+1 -> 63 | C65: =Database!A64 -> Tamas Mendik | D65: =VLOOKUP($C65,Database!$A:$B,2,0) -> 21
B66: =B65+1 -> 64 | C66: =Database!A65 -> Matt Kennerson | D66: =VLOOKUP($C66,Database!$A:$B,2,0) -> 10
B67: =B66+1 -> 65 | C67: =Database!A66 -> Craig Broderick | D67: =VLOOKUP($C67,Database!$A:$B,2,0) -> 22
B68: =B67+1 -> 66 | C68: =Database!A67 -> Scott Griffiths | D68: =VLOOKUP($C68,Database!$A:$B,2,0) -> 17
B69: =B68+1 -> 67 | C69: =Database!A68 -> Nick Williams | D69: =VLOOKUP($C69,Database!$A:$B,2,0) -> 27

Sheet SAT LEADERBOARD
C1: {=SUM(INDIRECT("'"&$C47&"'!$m$2:$m$1000"))} -> 32
B2: SAT STABLEFORD - LEADERBOARD
B4: RANK | C4: PLAYER | D4: POINTS | E4: FRONT | F4: BACK | G4: THROUGH | H4: BIRDIES | I4: EAGLES
B5: =IF(D5>0,RANK(D5,D:D,0),"NA") -> 32 | C5: =Players!C3 -> Brendan Oakes | D5: =SUM(INDIRECT("'"&$C5&"'!$m$2:$m$1000")) -> 28 | E5: =SUMIF(INDIRECT("'"&$C5&"'!$d$2:$d$1000"),"Front",INDIRECT("'"&$C5&"'!$m$2:$m$1000")) -> 17 | F5: =SUMIF(INDIRECT("'"&$C5&"'!$d$2:$d$1000"),"Back",INDIRECT("'"&$C5&"'!$m$2:$m$1000")) -> 11 | G5: =COUNTIF(INDIRECT("'"&$C5&"'!$i$2:$i$1000"),"<>"&"") -> 18 | H5: =COUNTIF(INDIRECT("'"&$C5&"'!$j$2:$j$1000"),"<0") -> 0 | I5: =COUNTIF(INDIRECT("'"&$C5&"'!$j$2:$j$1000"),"<-1") -> 0
B6: =IF(D6>0,RANK(D6,D:D,0),"NA") -> 3 | C6: =Players!C4 -> Andrew Murray | D6: =SUM(INDIRECT("'"&$C6&"'!$m$2:$m$1000")) -> 41 | E6: =SUMIF(INDIRECT("'"&$C6&"'!$d$2:$d$1000"),"Front",INDIRECT("'"&$C6&"'!$m$2:$m$1000")) -> 19 | F6: =SUMIF(INDIRECT("'"&$C6&"'!$d$2:$d$1000"),"Back",INDIRECT("'"&$C6&"'!$m$2:$m$1000")) -> 22 | G6: =COUNTIF(INDIRECT("'"&$C6&"'!$i$2:$i$1000"),"<>"&"") -> 18 | H6: =COUNTIF(INDIRECT("'"&$C6&"'!$j$2:$j$1000"),"<0") -> 0 | I6: =COUNTIF(INDIRECT("'"&$C6&"'!$j$2:$j$1000"),"<-1") -> 0 | J6: =B6 -> 3
B7: =IF(D7>0,RANK(D7,D:D,0),"NA") -> 58 | C7: =Players!C5 -> Noel Jago | D7: =SUM(INDIRECT("'"&$C7&"'!$m$2:$m$1000")) -> 16 | E7: =SUMIF(INDIRECT("'"&$C7&"'!$d$2:$d$1000"),"Front",INDIRECT("'"&$C7&"'!$m$2:$m$1000")) -> 8 | F7: =SUMIF(INDIRECT("'"&$C7&"'!$d$2:$d$1000"),"Back",INDIRECT("'"&$C7&"'!$m$2:$m$1000")) -> 8 | G7: =COUNTIF(INDIRECT("'"&$C7&"'!$i$2:$i$1000"),"<>"&"") -> 18 | H7: =COUNTIF(INDIRECT("'"&$C7&"'!$j$2:$j$1000"),"<0") -> 0 | I7: =COUNTIF(INDIRECT("'"&$C7&"'!$j$2:$j$1000"),"<-1") -> 0 | J7: =B7 -> 58
B8: =IF(D8>0,RANK(D8,D:D,0),"NA") -> 42 | C8: =Players!C6 -> Peter Keen | D8: =SUM(INDIRECT("'"&$C8&"'!$m$2:$m$1000")) -> 25 | E8: =SUMIF(INDIRECT("'"&$C8&"'!$d$2:$d$1000"),"Front",INDIRECT("'"&$C8&"'!$m$2:$m$1000")) -> 7 | F8: =SUMIF(INDIRECT("'"&$C8&"'!$d$2:$d$1000"),"Back",INDIRECT("'"&$C8&"'!$m$2:$m$1000")) -> 18 | G8: =COUNTIF(INDIRECT("'"&$C8&"'!$i$2:$i$1000"),"<>"&"") -> 18 | H8: =COUNTIF(INDIRECT("'"&$C8&"'!$j$2:$j$1000"),"<0") -> 0 | I8: =COUNTIF(INDIRECT("'"&$C8&"'!$j$2:$j$1000"),"<-1") -> 0 | J8: =B8 -> 42
B9: =IF(D9>0,RANK(D9,D:D,0),"NA") -> 8 | C9: =Players!C7 -> Martyn Budden | D9: =SUM(INDIRECT("'"&$C9&"'!$m$2:$m$1000")) -> 36 | E9: =SUMIF(INDIRECT("'"&$C9&"'!$d$2:$d$1000"),"Front",INDIRECT("'"&$C9&"'!$m$2:$m$1000")) -> 17 | F9: =SUMIF(INDIRECT("'"&$C9&"'!$d$2:$d$1000"),"Back",INDIRECT("'"&$C9&"'!$m$2:$m$1000")) -> 19 | G9: =COUNTIF(INDIRECT("'"&$C9&"'!$i$2:$i$1000"),"<>"&"") -> 18 | H9: =COUNTIF(INDIRECT("'"&$C9&"'!$j$2:$j$1000"),"<0") -> 0 | I9: =COUNTIF(INDIRECT("'"&$C9&"'!$j$2:$j$1000"),"<-1") -> 0 | J9: =B9 -> 8
B10: =IF(D10>0,RANK(D10,D:D,0),"NA") -> 20 | C10: =Players!C8 -> Ashley Oakes | D10: =SUM(INDIRECT("'"&$C10&"'!$m$2:$m$1000")) -> 31 | E10: =SUMIF(INDIRECT("'"&$C10&"'!$d$2:$d$1000"),"Front",INDIRECT("'"&$C10&"'!$m$2:$m$1000")) -> 16 | F10: =SUMIF(INDIRECT("'"&$C10&"'!$d$2:$d$1000"),"Back",INDIRECT("'"&$C10&"'!$m$2:$m$1000")) -> 15 | G10: =COUNTIF(INDIRECT("'"&$C10&"'!$i$2:$i$1000"),"<>"&"") -> 18 | H10: =COUNTIF(INDIRECT("'"&$C10&"'!$j$2:$j$1000"),"<0") -> 0 | I10: =COUNTIF(INDIRECT("'"&$C10&"'!$j$2:$j$1000"),"<-1") -> 0 | J10: =B10 -> 20
B11: =IF(D11>0,RANK(D11,D:D,0),"NA") -> 52 | C11: =Players!C9 -> Matt Jackson | D11: =SUM(INDIRECT("'"&$C11&"'!$m$2:$m$1000")) -> 21 | E11: =SUMIF(INDIRECT("'"&$C11&"'!$d$2:$d$1000"),"Front",INDIRECT("'"&$C11&"'!$m$2:$m$1000")) -> 6 | F11: =SUMIF(INDIRECT("'"&$C11&"'!$d$2:$d$1000"),"Back",INDIRECT("'"&$C11&"'!$m$2:$m$1000")) -> 15 | G11: =COUNTIF(INDIRECT("'"&$C11&"'!$i$2:$i$1000"),"<>"&"") -> 18 | H11: =COUNTIF(INDIRECT("'"&$C11&"'!$j$2:$j$1000"),"<0") -> 0 | I11: =COUNTIF(INDIRECT("'"&$C11&"'!$j$2:$j$1000"),"<-1") -> 0 | J11: =B11 -> 52
B12: =IF(D12>0,RANK(D12,D:D,0),"NA") -> 45 | C12: =Players!C10 -> Phil Carney | D12: =SUM(INDIRECT("'"&$C12&"'!$m$2:$m$1000")) -> 24 | E12: =SUMIF(INDIRECT("'"&$C12&"'!$d$2:$d$1000"),"Front",INDIRECT("'"&$C12&"'!$m$2:$m$1000")) -> 12 | F12: =SUMIF(INDIRECT("'"&$C12&"'!$d$2:$d$1000"),"Back",INDIRECT("'"&$C12&"'!$m$2:$m$1000")) -> 12 | G12: =COUNTIF(INDIRECT("'"&$C12&"'!$i$2:$i$1000"),"<>"&"") -> 18 | H12: =COUNTIF(INDIRECT("'"&$C12&"'!$j$2:$j$1000"),"<0") -> 0 | I12: =COUNTIF(INDIRECT("'"&$C12&"'!$j$2:$j$1000"),"<-1") -> 0 | J12: =B12 -> 45
B13: =IF(D13>0,RANK(D13,D:D,0),"NA") -> 45 | C13: =Players!C11 -> Chris Chilcott | D13: =SUM(INDIRECT("'"&$C13&"'!$m$2:$m$1000")) -> 24 | E13: =SUMIF(INDIRECT("'"&$C13&"'!$d$2:$d$1000"),"Front",INDIRECT("'"&$C13&"'!$m$2:$m$1000")) -> 13 | F13: =SUMIF(INDIRECT("'"&$C13&"'!$d$2:$d$1000"),"Back",INDIRECT("'"&$C13&"'!$m$2:$m$1000")) -> 11 | G13: =COUNTIF(INDIRECT("'"&$C13&"'!$i$2:$i$1000"),"<>"&"") -> 18 | H13: =COUNTIF(INDIRECT("'"&$C13&"'!$j$2:$j$1000"),"<0") -> 0 | I13: =COUNTIF(INDIRECT("'"&$C13&"'!$j$2:$j$1000"),"<-1") -> 0 | J13: =B13 -> 45
B14: =IF(D14>0,RANK(D14,D:D,0),"NA") -> 63 | C14: =Players!C12 -> Damien Starcic | D14: =SUM(INDIRECT("'"&$C14&"'!$m$2:$m$1000")) -> 6 | E14: =SUMIF(INDIRECT("'"&$C14&"'!$d$2:$d$1000"),"Front",INDIRECT("'"&$C14&"'!$m$2:$m$1000")) -> 6 | F14: =SUMIF(INDIRECT("'"&$C14&"'!$d$2:$d$1000"),"Back",INDIRECT("'"&$C14&"'!$m$2:$m$1000")) -> 0 | G14: =COUNTIF(INDIRECT("'"&$C14&"'!$i$2:$i$1000"),"<>"&"") -> 18 | H14: =COUNTIF(INDIRECT("'"&$C14&"'!$j$2:$j$1000"),"<0") -> 0 | I14: =COUNTIF(INDIRECT("'"&$C14&"'!$j$2:$j$1000"),"<-1") -> 0 | J14: =B14 -> 63
B15: =IF(D15>0,RANK(D15,D:D,0),"NA") -> 29 | C15: =Players!C13 -> Daniel Graham | D15: =SUM(INDIRECT("'"&$C15&"'!$m$2:$m$1000")) -> 29 | E15: =SUMIF(INDIRECT("'"&$C15&"'!$d$2:$d$1000"),"Front",INDIRECT("'"&$C15&"'!$m$2:$m$1000")) -> 14 | F15: =SUMIF(INDIRECT("'"&$C15&"'!$d$2:$d$1000"),"Back",INDIRECT("'"&$C15&"'!$m$2:$m$1000")) -> 15 | G15: =COUNTIF(INDIRECT("'"&$C15&"'!$i$2:$i$1000"),"<>"&"") -> 18 | H15: =COUNTIF(INDIRECT("'"&$C15&"'!$j$2:$j$1000"),"<0") -> 1 | I15: =COUNTIF(INDIRECT("'"&$C15&"'!$j$2:$j$1000"),"<-1") -> 0 | J15: =B15 -> 29
B16: =IF(D16>0,RANK(D16,D:D,0),"NA") -> 38 | C16: =Players!C14 -> Adam Paton | D16: =SUM(INDIRECT("'"&$C16&"'!$m$2:$m$1000")) -> 26 | E16: =SUMIF(INDIRECT("'"&$C16&"'!$d$2:$d$1000"),"Front",INDIRECT("'"&$C16&"'!$m$2:$m$1000")) -> 14 | F16: =SUMIF(INDIRECT("'"&$C16&"'!$d$2:$d$1000"),"Back",INDIRECT("'"&$C16&"'!$m$2:$m$1000")) -> 12 | G16: =COUNTIF(INDIRECT("'"&$C16&"'!$i$2:$i$1000"),"<>"&"") -> 18 | H16: =COUNTIF(INDIRECT("'"&$C16&"'!$j$2:$j$1000"),"<0") -> 0 | I16: =COUNTIF(INDIRECT("'"&$C16&"'!$j$2:$j$1000"),"<-1") -> 0 | J16: =B16 -> 38
B17: =IF(D17>0,RANK(D17,D:D,0),"NA") -> 38 | C17: =Players!C15 -> Matt Rowan | D17: =SUM(INDIRECT("'"&$C17&"'!$m$2:$m$1000")) -> 26 | E17: =SUMIF(INDIRECT("'"&$C17&"'!$d$2:$d$1000"),"Front",INDIRECT("'"&$C17&"'!$m$2:$m$1000")) -> 13 | F17: =SUMIF(INDIRECT("'"&$C17&"'!$d$2:$d$1000"),"Back",INDIRECT("'"&$C17&"'!$m$2:$m$1000")) -> 13 | G17: =COUNTIF(INDIRECT("'"&$C17&"'!$i$2:$i$1000"),"<>"&"") -> 18 | H17: =COUNTIF(INDIRECT("'"&$C17&"'!$j$2:$j$1000"),"<0") -> 0 | I17: =COUNTIF(INDIRECT("'"&$C17&"'!$j$2:$j$1000"),"<-1") -> 0 | J17: =B17 -> 38
B18: =IF(D18>0,RANK(D18,D:D,0),"NA") -> 20 | C18: =Players!C16 -> Steve Press | D18: =SUM(INDIRECT("'"&$C18&"'!$m$2:$m$1000")) -> 31 | E18: =SUMIF(INDIRECT("'"&$C18&"'!$d$2:$d$1000"),"Front",INDIRECT("'"&$C18&"'!$m$2:$m$1000")) -> 13 | F18: =SUMIF(INDIRECT("'"&$C18&"'!$d$2:$d$1000"),"Back",INDIRECT("'"&$C18&"'!$m$2:$m$1000")) -> 18 | G18: =COUNTIF(INDIRECT("'"&$C18&"'!$i$2:$i$1000"),"<>"&"") -> 18 | H18: =COUNTIF(INDIRECT("'"&$C18&"'!$j$2:$j$1000"),"<0") -> 1 | I18: =COUNTIF(INDIRECT("'"&$C18&"'!$j$2:$j$1000"),"<-1") -> 0 | J18: =B18 -> 20
B19: =IF(D19>0,RANK(D19,D:D,0),"NA") -> 32 | C19: =Players!C18 -> Darryn Rooks | D19: =SUM(INDIRECT("'"&$C19&"'!$m$2:$m$1000")) -> 28 | E19: =SUMIF(INDIRECT("'"&$C19&"'!$d$2:$d$1000"),"Front",INDIRECT("'"&$C19&"'!$m$2:$m$1000")) -> 15 | F19: =SUMIF(INDIRECT("'"&$C19&"'!$d$2:$d$1000"),"Back",INDIRECT("'"&$C19&"'!$m$2:$m$1000")) -> 13 | G19: =COUNTIF(INDIRECT("'"&$C19&"'!$i$2:$i$1000"),"<>"&"") -> 18 | H19: =COUNTIF(INDIRECT("'"&$C19&"'!$j$2:$j$1000"),"<0") -> 0 | I19: =COUNTIF(INDIRECT("'"&$C19&"'!$j$2:$j$1000"),"<-1") -> 0 | J19: =B19 -> 32
B20: =IF(D20>0,RANK(D20,D:D,0),"NA") -> 11 | C20: =Players!C19 -> Josh Fryer | D20: =SUM(INDIRECT("'"&$C20&"'!$m$2:$m$1000")) -> 34 | E20: =SUMIF(INDIRECT("'"&$C20&"'!$d$2:$d$1000"),"Front",INDIRECT("'"&$C20&"'!$m$2:$m$1000")) -> 16 | F20: =SUMIF(INDIRECT("'"&$C20&"'!$d$2:$d$1000"),"Back",INDIRECT("'"&$C20&"'!$m$2:$m$1000")) -> 18 | G20: =COUNTIF(INDIRECT("'"&$C20&"'!$i$2:$i$1000"),"<>"&"") -> 18 | H20: =COUNTIF(INDIRECT("'"&$C20&"'!$j$2:$j$1000"),"<0") -> 1 | I20: =COUNTIF(INDIRECT("'"&$C20&"'!$j$2:$j$1000"),"<-1") -> 0 | J20: =B20 -> 11
B21: =IF(D21>0,RANK(D21,D:D,0),"NA") -> 20 | C21: =Players!C20 -> Scott Austin | D21: =SUM(INDIRECT("'"&$C21&"'!$m$2:$m$1000")) -> 31 | E21: =SUMIF(INDIRECT("'"&$C21&"'!$d$2:$d$1000"),"Front",INDIRECT("'"&$C21&"'!$m$2:$m$1000")) -> 14 | F21: =SUMIF(INDIRECT("'"&$C21&"'!$d$2:$d$1000"),"Back",INDIRECT("'"&$C21&"'!$m$2:$m$1000")) -> 17 | G21: =COUNTIF(INDIRECT("'"&$C21&"'!$i$2:$i$1000"),"<>"&"") -> 18 | H21: =COUNTIF(INDIRECT("'"&$C21&"'!$j$2:$j$1000"),"<0") -> 1 | I21: =COUNTIF(INDIRECT("'"&$C21&"'!$j$2:$j$1000"),"<-1") -> 0 | J21: =B21 -> 20
B22: =IF(D22>0,RANK(D22,D:D,0),"NA") -> 42 | C22: =Players!C21 -> Mark Lever | D22: =SUM(INDIRECT("'"&$C22&"'!$m$2:$m$1000")) -> 25 | E22: =SUMIF(INDIRECT("'"&$C22&"'!$d$2:$d$1000"),"Front",INDIRECT("'"&$C22&"'!$m$2:$m$1000")) -> 15 | F22: =SUMIF(INDIRECT("'"&$C22&"'!$d$2:$d$1000"),"Back",INDIRECT("'"&$C22&"'!$m$2:$m$1000")) -> 10 | G22: =COUNTIF(INDIRECT("'"&$C22&"'!$i$2:$i$1000"),"<>"&"") -> 18 | H22: =COUNTIF(INDIRECT("'"&$C22&"'!$j$2:$j$1000"),"<0") -> 0 | I22: =COUNTIF(INDIRECT("'"&$C22&"'!$j$2:$j$1000"),"<-1") -> 0 | J22: =B22 -> 42
B23: =IF(D23>0,RANK(D23,D:D,0),"NA") -> 19 | C23: =Players!C22 -> Bruce Brown | D23: =SUM(INDIRECT("'"&$C23&"'!$m$2:$m$1000")) -> 32 | E23: =SUMIF(INDIRECT("'"&$C23&"'!$d$2:$d$1000"),"Front",INDIRECT("'"&$C23&"'!$m$2:$m$1000")) -> 13 | F23: =SUMIF(INDIRECT("'"&$C23&"'!$d$2:$d$1000"),"Back",INDIRECT("'"&$C23&"'!$m$2:$m$1000")) -> 19 | G23: =COUNTIF(INDIRECT("'"&$C23&"'!$i$2:$i$1000"),"<>"&"") -> 18 | H23: =COUNTIF(INDIRECT("'"&$C23&"'!$j$2:$j$1000"),"<0") -> 0 | I23: =COUNTIF(INDIRECT("'"&$C23&"'!$j$2:$j$1000"),"<-1") -> 0 | J23: =B23 -> 19
B24: =IF(D24>0,RANK(D24,D:D,0),"NA") -> 20 | C24: =Players!C23 -> Warren Gibson | D24: =SUM(INDIRECT("'"&$C24&"'!$m$2:$m$1000")) -> 31 | E24: =SUMIF(INDIRECT("'"&$C24&"'!$d$2:$d$1000"),"Front",INDIRECT("'"&$C24&"'!$m$2:$m$1000")) -> 16 | F24: =SUMIF(INDIRECT("'"&$C24&"'!$d$2:$d$1000"),"Back",INDIRECT("'"&$C24&"'!$m$2:$m$1000")) -> 15 | G24: =COUNTIF(INDIRECT("'"&$C24&"'!$i$2:$i$1000"),"<>"&"") -> 18 | H24: =COUNTIF(INDIRECT("'"&$C24&"'!$j$2:$j$1000"),"<0") -> 0 | I24: =COUNTIF(INDIRECT("'"&$C24&"'!$j$2:$j$1000"),"<-1") -> 0 | J24: =B24 -> 20
B25: =IF(D25>0,RANK(D25,D:D,0),"NA") -> 51 | C25: =Players!C24 -> Ernie Zibert | D25: =SUM(INDIRECT("'"&$C25&"'!$m$2:$m$1000")) -> 22 | E25: =SUMIF(INDIRECT("'"&$C25&"'!$d$2:$d$1000"),"Front",INDIRECT("'"&$C25&"'!$m$2:$m$1000")) -> 17 | F25: =SUMIF(INDIRECT("'"&$C25&"'!$d$2:$d$1000"),"Back",INDIRECT("'"&$C25&"'!$m$2:$m$1000")) -> 5 | G25: =COUNTIF(INDIRECT("'"&$C25&"'!$i$2:$i$1000"),"<>"&"") -> 18 | H25: =COUNTIF(INDIRECT("'"&$C25&"'!$j$2:$j$1000"),"<0") -> 1 | I25: =COUNTIF(INDIRECT("'"&$C25&"'!$j$2:$j$1000"),"<-1") -> 0 | J25: =B25 -> 51
B26: =IF(D26>0,RANK(D26,D:D,0),"NA") -> 11 | C26: =Players!C25 -> John Winter | D26: =SUM(INDIRECT("'"&$C26&"'!$m$2:$m$1000")) -> 34 | E26: =SUMIF(INDIRECT("'"&$C26&"'!$d$2:$d$1000"),"Front",INDIRECT("'"&$C26&"'!$m$2:$m$1000")) -> 15 | F26: =SUMIF(INDIRECT("'"&$C26&"'!$d$2:$d$1000"),"Back",INDIRECT("'"&$C26&"'!$m$2:$m$1000")) -> 19 | G26: =COUNTIF(INDIRECT("'"&$C26&"'!$i$2:$i$1000"),"<>"&"") -> 18 | H26: =COUNTIF(INDIRECT("'"&$C26&"'!$j$2:$j$1000"),"<0") -> 1 | I26: =COUNTIF(INDIRECT("'"&$C26&"'!$j$2:$j$1000"),"<-1") -> 0 | J26: =B26 -> 11
B27: =IF(D27>0,RANK(D27,D:D,0),"NA") -> 52 | C27: =Players!C26 -> Joe Pajeska | D27: =SUM(INDIRECT("'"&$C27&"'!$m$2:$m$1000")) -> 21 | E27: =SUMIF(INDIRECT("'"&$C27&"'!$d$2:$d$1000"),"Front",INDIRECT("'"&$C27&"'!$m$2:$m$1000")) -> 5 | F27: =SUMIF(INDIRECT("'"&$C27&"'!$d$2:$d$1000"),"Back",INDIRECT("'"&$C27&"'!$m$2:$m$1000")) -> 16 | G27: =COUNTIF(INDIRECT("'"&$C27&"'!$i$2:$i$1000"),"<>"&"") -> 18 | H27: =COUNTIF(INDIRECT("'"&$C27&"'!$j$2:$j$1000"),"<0") -> 1 | I27: =COUNTIF(INDIRECT("'"&$C27&"'!$j$2:$j$1000"),"<-1") -> 0 | J27: =B27 -> 52
B28: =IF(D28>0,RANK(D28,D:D,0),"NA") -> 7 | C28: =Players!C27 -> Brad Grant | D28: =SUM(INDIRECT("'"&$C28&"'!$m$2:$m$1000")) -> 37 | E28: =SUMIF(INDIRECT("'"&$C28&"'!$d$2:$d$1000"),"Front",INDIRECT("'"&$C28&"'!$m$2:$m$1000")) -> 19 | F28: =SUMIF(INDIRECT("'"&$C28&"'!$d$2:$d$1000"),"Back",INDIRECT("'"&$C28&"'!$m$2:$m$1000")) -> 18 | G28: =COUNTIF(INDIRECT("'"&$C28&"'!$i$2:$i$1000"),"<>"&"") -> 18 | H28: =COUNTIF(INDIRECT("'"&$C28&"'!$j$2:$j$1000"),"<0") -> 0 | I28: =COUNTIF(INDIRECT("'"&$C28&"'!$j$2:$j$1000"),"<-1") -> 0 | J28: =B28 -> 7
B29: =IF(D29>0,RANK(D29,D:D,0),"NA") -> 11 | C29: =Players!C28 -> Andrew Graham | D29: =SUM(INDIRECT("'"&$C29&"'!$m$2:$m$1000")) -> 34 | E29: =SUMIF(INDIRECT("'"&$C29&"'!$d$2:$d$1000"),"Front",INDIRECT("'"&$C29&"'!$m$2:$m$1000")) -> 16 | F29: =SUMIF(INDIRECT("'"&$C29&"'!$d$2:$d$1000"),"Back",INDIRECT("'"&$C29&"'!$m$2:$m$1000")) -> 18 | G29: =COUNTIF(INDIRECT("'"&$C29&"'!$i$2:$i$1000"),"<>"&"") -> 18 | H29: =COUNTIF(INDIRECT("'"&$C29&"'!$j$2:$j$1000"),"<0") -> 1 | I29: =COUNTIF(INDIRECT("'"&$C29&"'!$j$2:$j$1000"),"<-1") -> 0 | J29: =B29 -> 11
B30: =IF(D30>0,RANK(D30,D:D,0),"NA") -> 15 | C30: =Players!C29 -> Glenn Palmer | D30: =SUM(INDIRECT("'"&$C30&"'!$m$2:$m$1000")) -> 33 | E30: =SUMIF(INDIRECT("'"&$C30&"'!$d$2:$d$1000"),"Front",INDIRECT("'"&$C30&"'!$m$2:$m$1000")) -> 17 | F30: =SUMIF(INDIRECT("'"&$C30&"'!$d$2:$d$1000"),"Back",INDIRECT("'"&$C30&"'!$m$2:$m$1000")) -> 16 | G30: =COUNTIF(INDIRECT("'"&$C30&"'!$i$2:$i$1000"),"<>"&"") -> 18 | H30: =COUNTIF(INDIRECT("'"&$C30&"'!$j$2:$j$1000"),"<0") -> 0 | I30: =COUNTIF(INDIRECT("'"&$C30&"'!$j$2:$j$1000"),"<-1") -> 0 | J30: =B30 -> 15
... B46: =IF(D46>0,RANK(D46,D:D,0),"NA") -> 3 | C46: =Players!C45 -> Mark Anderson | D46: =SUM(INDIRECT("'"&$C46&"'!$m$2:$m$1000")) -> 41 | E46: =SUMIF(INDIRECT("'"&$C46&"'!$d$2:$d$1000"),"Front",INDIRECT("'"&$C46&"'!$m$2:$m$1000")) -> 22 | F46: =SUMIF(INDIRECT("'"&$C46&"'!$d$2:$d$1000"),"Back",INDIRECT("'"&$C46&"'!$m$2:$m$1000")) -> 19 | G46: =COUNTIF(INDIRECT("'"&$C46&"'!$i$2:$i$1000"),"<>"&"") -> 18 | H46: =COUNTIF(INDIRECT("'"&$C46&"'!$j$2:$j$1000"),"<0") -> 0 | I46: =COUNTIF(INDIRECT("'"&$C46&"'!$j$2:$j$1000"),"<-1") -> 0 | J46: =B46 -> 3
B47: =IF(C1>0,RANK(C1,D:D,0),"NA") -> 19 | C47: =Players!C46 -> Glen Duley | E47: =SUMIF(INDIRECT("'"&$C47&"'!$d$2:$d$1000"),"Front",INDIRECT("'"&$C47&"'!$m$2:$m$1000")) -> 14 | F47: =SUMIF(INDIRECT("'"&$C47&"'!$d$2:$d$1000"),"Back",INDIRECT("'"&$C47&"'!$m$2:$m$1000")) -> 18 | G47: =COUNTIF(INDIRECT("'"&$C47&"'!$i$2:$i$1000"),"<>"&"") -> 18 | H47: =COUNTIF(INDIRECT("'"&$C47&"'!$j$2:$j$1000"),"<0") -> 0 | I47: =COUNTIF(INDIRECT("'"&$C47&"'!$j$2:$j$1000"),"<-1") -> 0 | J47: =B47 -> 19
B48: =IF(D48>0,RANK(D48,D:D,0),"NA") -> 36 | C48: =Players!C47 -> Ed Howitt | D48: =SUM(INDIRECT("'"&$C48&"'!$m$2:$m$1000")) -> 27 | E48: =SUMIF(INDIRECT("'"&$C48&"'!$d$2:$d$1000"),"Front",INDIRECT("'"&$C48&"'!$m$2:$m$1000")) -> 10 | F48: =SUMIF(INDIRECT("'"&$C48&"'!$d$2:$d$1000"),"Back",INDIRECT("'"&$C48&"'!$m$2:$m$1000")) -> 17 | G48: =COUNTIF(INDIRECT("'"&$C48&"'!$i$2:$i$1000"),"<>"&"") -> 18 | H48: =COUNTIF(INDIRECT("'"&$C48&"'!$j$2:$j$1000"),"<0") -> 0 | I48: =COUNTIF(INDIRECT("'"&$C48&"'!$j$2:$j$1000"),"<-1") -> 0 | J48: =B48 -> 36
B49: =IF(D49>0,RANK(D49,D:D,0),"NA") -> 15 | C49: =Players!C48 -> Michael Lagudi | D49: =SUM(INDIRECT("'"&$C49&"'!$m$2:$m$1000")) -> 33 | E49: =SUMIF(INDIRECT("'"&$C49&"'!$d$2:$d$1000"),"Front",INDIRECT("'"&$C49&"'!$m$2:$m$1000")) -> 16 | F49: =SUMIF(INDIRECT("'"&$C49&"'!$d$2:$d$1000"),"Back",INDIRECT("'"&$C49&"'!$m$2:$m$1000")) -> 17 | G49: =COUNTIF(INDIRECT("'"&$C49&"'!$i$2:$i$1000"),"<>"&"") -> 18 | H49: =COUNTIF(INDIRECT("'"&$C49&"'!$j$2:$j$1000"),"<0") -> 1 | I49: =COUNTIF(INDIRECT("'"&$C49&"'!$j$2:$j$1000"),"<-1") -> 0 | J49: =B49 -> 15
B50: =IF(D50>0,RANK(D50,D:D,0),"NA") -> 38 | C50: =Players!C49 -> Paul McLean | D50: =SUM(INDIRECT("'"&$C50&"'!$m$2:$m$1000")) -> 26 | E50: =SUMIF(INDIRECT("'"&$C50&"'!$d$2:$d$1000"),"Front",INDIRECT("'"&$C50&"'!$m$2:$m$1000")) -> 13 | F50: =SUMIF(INDIRECT("'"&$C50&"'!$d$2:$d$1000"),"Back",INDIRECT("'"&$C50&"'!$m$2:$m$1000")) -> 13 | G50: =COUNTIF(INDIRECT("'"&$C50&"'!$i$2:$i$1000"),"<>"&"") -> 18 | H50: =COUNTIF(INDIRECT("'"&$C50&"'!$j$2:$j$1000"),"<0") -> 0 | I50: =COUNTIF(INDIRECT("'"&$C50&"'!$j$2:$j$1000"),"<-1") -> 0 | J50: =B50 -> 38
B51: =IF(D51>0,RANK(D51,D:D,0),"NA") -> 54 | C51: =Players!C50 -> Riley Oakes | D51: =SUM(INDIRECT("'"&$C51&"'!$m$2:$m$1000")) -> 20 | E51: =SUMIF(INDIRECT("'"&$C51&"'!$d$2:$d$1000"),"Front",INDIRECT("'"&$C51&"'!$m$2:$m$1000")) -> 12 | F51: =SUMIF(INDIRECT("'"&$C51&"'!$d$2:$d$1000"),"Back",INDIRECT("'"&$C51&"'!$m$2:$m$1000")) -> 8 | G51: =COUNTIF(INDIRECT("'"&$C51&"'!$i$2:$i$1000"),"<>"&"") -> 18 | H51: =COUNTIF(INDIRECT("'"&$C51&"'!$j$2:$j$1000"),"<0") -> 2 | I51: =COUNTIF(INDIRECT("'"&$C51&"'!$j$2:$j$1000"),"<-1") -> 1 | J51: =B51 -> 54
B52: =IF(D52>0,RANK(D52,D:D,0),"NA") -> 61 | C52: =Players!C51 -> Joel Shepherd | D52: =SUM(INDIRECT("'"&$C52&"'!$m$2:$m$1000")) -> 13 | E52: =SUMIF(INDIRECT("'"&$C52&"'!$d$2:$d$1000"),"Front",INDIRECT("'"&$C52&"'!$m$2:$m$1000")) -> 3 | F52: =SUMIF(INDIRECT("'"&$C52&"'!$d$2:$d$1000"),"Back",INDIRECT("'"&$C52&"'!$m$2:$m$1000")) -> 10 | G52: =COUNTIF(INDIRECT("'"&$C52&"'!$i$2:$i$1000"),"<>"&"") -> 18 | H52: =COUNTIF(INDIRECT("'"&$C52&"'!$j$2:$j$1000"),"<0") -> 0 | I52: =COUNTIF(INDIRECT("'"&$C52&"'!$j$2:$j$1000"),"<-1") -> 0 | J52: =B52 -> 61
B53: =IF(D53>0,RANK(D53,D:D,0),"NA") -> 25 | C53: =Players!C52 -> Glenn Hickey | D53: =SUM(INDIRECT("'"&$C53&"'!$m$2:$m$1000")) -> 30 | E53: =SUMIF(INDIRECT("'"&$C53&"'!$d$2:$d$1000"),"Front",INDIRECT("'"&$C53&"'!$m$2:$m$1000")) -> 11 | F53: =SUMIF(INDIRECT("'"&$C53&"'!$d$2:$d$1000"),"Back",INDIRECT("'"&$C53&"'!$m$2:$m$1000")) -> 19 | G53: =COUNTIF(INDIRECT("'"&$C53&"'!$i$2:$i$1000"),"<>"&"") -> 18 | H53: =COUNTIF(INDIRECT("'"&$C53&"'!$j$2:$j$1000"),"<0") -> 2 | I53: =COUNTIF(INDIRECT("'"&$C53&"'!$j$2:$j$1000"),"<-1") -> 0 | J53: =B53 -> 25
B54: =IF(D54>0,RANK(D54,D:D,0),"NA") -> 58 | C54: =Players!C53 -> Jordan Whitehorn | D54: =SUM(INDIRECT("'"&$C54&"'!$m$2:$m$1000")) -> 16 | E54: =SUMIF(INDIRECT("'"&$C54&"'!$d$2:$d$1000"),"Front",INDIRECT("'"&$C54&"'!$m$2:$m$1000")) -> 4 | F54: =SUMIF(INDIRECT("'"&$C54&"'!$d$2:$d$1000"),"Back",INDIRECT("'"&$C54&"'!$m$2:$m$1000")) -> 12 | G54: =COUNTIF(INDIRECT("'"&$C54&"'!$i$2:$i$1000"),"<>"&"") -> 18 | H54: =COUNTIF(INDIRECT("'"&$C54&"'!$j$2:$j$1000"),"<0") -> 0 | I54: =COUNTIF(INDIRECT("'"&$C54&"'!$j$2:$j$1000"),"<-1") -> 0 | J54: =B54 -> 58
B55: =IF(D55>0,RANK(D55,D:D,0),"NA") -> 64 | C55: =Players!C54 -> Greg Gomes | D55: =SUM(INDIRECT("'"&$C55&"'!$m$2:$m$1000")) -> 3 | E55: =SUMIF(INDIRECT("'"&$C55&"'!$d$2:$d$1000"),"Front",INDIRECT("'"&$C55&"'!$m$2:$m$1000")) -> 3 | F55: =SUMIF(INDIRECT("'"&$C55&"'!$d$2:$d$1000"),"Back",INDIRECT("'"&$C55&"'!$m$2:$m$1000")) -> 0 | G55: =COUNTIF(INDIRECT("'"&$C55&"'!$i$2:$i$1000"),"<>"&"") -> 18 | H55: =COUNTIF(INDIRECT("'"&$C55&"'!$j$2:$j$1000"),"<0") -> 0 | I55: =COUNTIF(INDIRECT("'"&$C55&"'!$j$2:$j$1000"),"<-1") -> 0 | J55: =B55 -> 64
B56: =IF(D56>0,RANK(D56,D:D,0),"NA") -> 42 | C56: =Players!C55 -> Ben Wood | D56: =SUM(INDIRECT("'"&$C56&"'!$m$2:$m$1000")) -> 25 | E56: =SUMIF(INDIRECT("'"&$C56&"'!$d$2:$d$1000"),"Front",INDIRECT("'"&$C56&"'!$m$2:$m$1000")) -> 13 | F56: =SUMIF(INDIRECT("'"&$C56&"'!$d$2:$d$1000"),"Back",INDIRECT("'"&$C56&"'!$m$2:$m$1000")) -> 12 | G56: =COUNTIF(INDIRECT("'"&$C56&"'!$i$2:$i$1000"),"<>"&"") -> 18 | H56: =COUNTIF(INDIRECT("'"&$C56&"'!$j$2:$j$1000"),"<0") -> 1 | I56: =COUNTIF(INDIRECT("'"&$C56&"'!$j$2:$j$1000"),"<-1") -> 0 | J56: =B56 -> 42
...

Sheet Sheet2

Sheet Brendan Oakes
A1: LOOKUP | B1: COURSE | C1: PLAYER | D1: CATEGORY | E1: HOLE | F1: PAR | G1: INDEX 1 | H1: INDEX 2 | I1: SCORE | J1: OVER | K1: DOUBLE | L1: NO SHOT | M1: POINTS | N1: 4 OR 5 POINTER? | O1: LAST 6 | P1: ACC SCORE | Q1: ACC STAB | R1: HANDICAP | S1: DOUBLE? | T1: NO SHOT? | U1: NETT | V1: RANK
A2: 1 | B2: Worrigee | C2: =Players!C3 -> Brendan Oakes | D2: FRONT | E2: 1 | F2: =SUMIFS('Course Info'!$D:$D,'Course Info'!$B:$B,$B2,'Course Info'!$C:$C,$E2) -> 5 | G2: =SUMIFS('Course Info'!$E:$E,'Course Info'!$B:$B,$B2,'Course Info'!$C:$C,$E2) -> 10 | H2: =SUMIFS('Course Info'!$F:$F,'Course Info'!$B:$B,$B2,'Course Info'!$C:$C,$E2) -> 23 | I2: 6 | J2: =IF(I2=0,(10-F2),I2-F2) -> 1 | K2: =IF(VLOOKUP($C2,Players!$C:$D,2,0)>H2,"YES",IF(VLOOKUP($C2,Players!$C:$D,2,0)=H2,"YES","NO")) -> NO | L2: =IF(VLOOKUP($C2,Players!$C:$D,2,0)>17,"NO",IF(VLOOKUP($C2,Players!$C:$D,2,0)<G2,"YES","NO")) -> NO | M2: =IFERROR(IF(I2="","",IF(VLOOKUP($C2,Players!$C:$D,2,0)>18,IF(K2="NO",IF(J2>2,0,3-J2),IF(J2>3,0,4-J2)),IF(L2="NO",IF(J2>2,0,3-J2),IF(J2>1,0,2-J2)))),0) -> 2 | N2: =IF(I2="","",IF(M2>3,"YES","NO")) -> NO | O2: =IF(E2>12,"YES","NO") -> NO | Q2: =SUM(M:M) -> 28 | S2: =IF(K2="YES",1,0) -> 0 | T2: =IF(L2="YES",1,0) -> 0 | U2: =IF(I2="","",I2-1-S2+T2) -> 5
A3: =A2 -> 1 | B3: =$B$2 -> Worrigee | C3: =C2 -> Brendan Oakes | D3: FRONT | E3: 2 | F3: =SUMIFS('Course Info'!$D:$D,'Course Info'!$B:$B,$B3,'Course Info'!$C:$C,$E3) -> 3 | G3: =SUMIFS('Course Info'!$E:$E,'Course Info'!$B:$B,$B3,'Course Info'!$C:$C,$E3) -> 1 | H3: =SUMIFS('Course Info'!$F:$F,'Course Info'!$B:$B,$B3,'Course Info'!$C:$C,$E3) -> 26 | I3: 5 | J3: =IF(I3=0,(10-F3),I3-F3) -> 2 | K3: =IF(VLOOKUP($C3,Players!$C:$D,2,0)>H3,"YES",IF(VLOOKUP($C3,Players!$C:$D,2,0)=H3,"YES","NO")) -> NO | L3: =IF(VLOOKUP($C3,Players!$C:$D,2,0)>17,"NO",IF(VLOOKUP($C3,Players!$C:$D,2,0)<G3,"YES","NO")) -> NO | M3: =IFERROR(IF(I3="","",IF(VLOOKUP($C3,Players!$C:$D,2,0)>18,IF(K3="NO",IF(J3>2,0,3-J3),IF(J3>3,0,4-J3)),IF(L3="NO",IF(J3>2,0,3-J3),IF(J3>1,0,2-J3)))),0) -> 1 | N3: =IF(I3="","",IF(M3>3,"YES","NO")) -> NO | O3: =IF(E3>12,"YES","NO") -> NO | Q3: =SUM(M:M) -> 28 | S3: =IF(K3="YES",1,0) -> 0 | T3: =IF(L3="YES",1,0) -> 0 | U3: =IF(I3="","",I3-1-S3+T3) -> 4
A4: =A3 -> 1 | B4: =$B$2 -> Worrigee | C4: =C3 -> Brendan Oakes | D4: FRONT | E4: 3 | F4: =SUMIFS('Course Info'!$D:$D,'Course Info'!$B:$B,$B4,'Course Info'!$C:$C,$E4) -> 4 | G4: =SUMIFS('Course Info'!$E:$E,'Course Info'!$B:$B,$B4,'Course Info'!$C:$C,$E4) -> 12 | H4: =SUMIFS('Course Info'!$F:$F,'Course Info'!$B:$B,$B4,'Course Info'!$C:$C,$E4) -> 29 | I4: 4 | J4: =IF(I4=0,(10-F4),I4-F4) -> 0 | K4: =IF(VLOOKUP($C4,Players!$C:$D,2,0)>H4,"YES",IF(VLOOKUP($C4,Players!$C:$D,2,0)=H4,"YES","NO")) -> NO | L4: =IF(VLOOKUP($C4,Players!$C:$D,2,0)>17,"NO",IF(VLOOKUP($C4,Players!$C:$D,2,0)<G4,"YES","NO")) -> NO | M4: =IFERROR(IF(I4="","",IF(VLOOKUP($C4,Players!$C:$D,2,0)>18,IF(K4="NO",IF(J4>2,0,3-J4),IF(J4>3,0,4-J4)),IF(L4="NO",IF(J4>2,0,3-J4),IF(J4>1,0,2-J4)))),0) -> 3 | N4: =IF(I4="","",IF(M4>3,"YES","NO")) -> NO | O4: =IF(E4>12,"YES","NO") -> NO | Q4: =SUM(M:M) -> 28 | S4: =IF(K4="YES",1,0) -> 0 | T4: =IF(L4="YES",1,0) -> 0 | U4: =IF(I4="","",I4-1-S4+T4) -> 3
A5: =A4 -> 1 | B5: =$B$2 -> Worrigee | C5: =C4 -> Brendan Oakes | D5: FRONT | E5: 4 | F5: =SUMIFS('Course Info'!$D:$D,'Course Info'!$B:$B,$B5,'Course Info'!$C:$C,$E5) -> 4 | G5: =SUMIFS('Course Info'!$E:$E,'Course Info'!$B:$B,$B5,'Course Info'!$C:$C,$E5) -> 16 | H5: =SUMIFS('Course Info'!$F:$F,'Course Info'!$B:$B,$B5,'Course Info'!$C:$C,$E5) -> 32 | I5: 4 | J5: =IF(I5=0,(10-F5),I5-F5) -> 0 | K5: =IF(VLOOKUP($C5,Players!$C:$D,2,0)>H5,"YES",IF(VLOOKUP($C5,Players!$C:$D,2,0)=H5,"YES","NO")) -> NO | L5: =IF(VLOOKUP($C5,Players!$C:$D,2,0)>17,"NO",IF(VLOOKUP($C5,Players!$C:$D,2,0)<G5,"YES","NO")) -> NO | M5: =IFERROR(IF(I5="","",IF(VLOOKUP($C5,Players!$C:$D,2,0)>18,IF(K5="NO",IF(J5>2,0,3-J5),IF(J5>3,0,4-J5)),IF(L5="NO",IF(J5>2,0,3-J5),IF(J5>1,0,2-J5)))),0) -> 3 | N5: =IF(I5="","",IF(M5>3,"YES","NO")) -> NO | O5: =IF(E5>12,"YES","NO") -> NO | Q5: =SUM(M:M) -> 28 | S5: =IF(K5="YES",1,0) -> 0 | T5: =IF(L5="YES",1,0) -> 0 | U5: =IF(I5="","",I5-1-S5+T5) -> 3
A6: =A5 -> 1 | B6: =$B$2 -> Worrigee | C6: =C5 -> Brendan Oakes | D6: FRONT | E6: 5 | F6: =SUMIFS('Course Info'!$D:$D,'Course Info'!$B:$B,$B6,'Course Info'!$C:$C,$E6) -> 4 | G6: =SUMIFS('Course Info'!$E:$E,'Course Info'!$B:$B,$B6,'Course Info'!$C:$C,$E6) -> 3 | H6: =SUMIFS('Course Info'!$F:$F,'Course Info'!$B:$B,$B6,'Course Info'!$C:$C,$E6) -> 21 | I6: 6 | J6: =IF(I6=0,(10-F6),I6-F6) -> 2 | K6: =IF(VLOOKUP($C6,Players!$C:$D,2,0)>H6,"YES",IF(VLOOKUP($C6,Players!$C:$D,2,0)=H6,"YES","NO")) -> NO | L6: =IF(VLOOKUP($C6,Players!$C:$D,2,0)>17,"NO",IF(VLOOKUP($C6,Players!$C:$D,2,0)<G6,"YES","NO")) -> NO | M6: =IFERROR(IF(I6="","",IF(VLOOKUP($C6,Players!$C:$D,2,0)>18,IF(K6="NO",IF(J6>2,0,3-J6),IF(J6>3,0,4-J6)),IF(L6="NO",IF(J6>2,0,3-J6),IF(J6>1,0,2-J6)))),0) -> 1 | N6: =IF(I6="","",IF(M6>3,"YES","NO")) -> NO | O6: =IF(E6>12,"YES","NO") -> NO | Q6: =SUM(M:M) -> 28 | S6: =IF(K6="YES",1,0) -> 0 | T6: =IF(L6="YES",1,0) -> 0 | U6: =IF(I6="","",I6-1-S6+T6) -> 5
A7: =A6 -> 1 | B7: =$B$2 -> Worrigee | C7: =C6 -> Brendan Oakes | D7: FRONT | E7: 6 | F7: =SUMIFS('Course Info'!$D:$D,'Course Info'!$B:$B,$B7,'Course Info'!$C:$C,$E7) -> 3 | G7: =SUMIFS('Course Info'!$E:$E,'Course Info'!$B:$B,$B7,'Course Info'!$C:$C,$E7) -> 15 | H7: =SUMIFS('Course Info'!$F:$F,'Course Info'!$B:$B,$B7,'Course Info'!$C:$C,$E7) -> 36 | I7: 4 | J7: =IF(I7=0,(10-F7),I7-F7) -> 1 | K7: =IF(VLOOKUP($C7,Players!$C:$D,2,0)>H7,"YES",IF(VLOOKUP($C7,Players!$C:$D,2,0)=H7,"YES","NO")) -> NO | L7: =IF(VLOOKUP($C7,Players!$C:$D,2,0)>17,"NO",IF(VLOOKUP($C7,Players!$C:$D,2,0)<G7,"YES","NO")) -> NO | M7: =IFERROR(IF(I7="","",IF(VLOOKUP($C7,Players!$C:$D,2,0)>18,IF(K7="NO",IF(J7>2,0,3-J7),IF(J7>3,0,4-J7)),IF(L7="NO",IF(J7>2,0,3-J7),IF(J7>1,0,2-J7)))),0) -> 2 | N7: =IF(I7="","",IF(M7>3,"YES","NO")) -> NO | O7: =IF(E7>12,"YES","NO") -> NO | Q7: =SUM(M:M) -> 28 | S7: =IF(K7="YES",1,0) -> 0 | T7: =IF(L7="YES",1,0) -> 0 | U7: =IF(I7="","",I7-1-S7+T7) -> 3
A8: =A7 -> 1 | B8: =$B$2 -> Worrigee | C8: =C7 -> Brendan Oakes | D8: FRONT | E8: 7 | F8: =SUMIFS('Course Info'!$D:$D,'Course Info'!$B:$B,$B8,'Course Info'!$C:$C,$E8) -> 5 | G8: =SUMIFS('Course Info'!$E:$E,'Course Info'!$B:$B,$B8,'Course Info'!$C:$C,$E8) -> 6 | H8: =SUMIFS('Course Info'!$F:$F,'Course Info'!$B:$B,$B8,'Course Info'!$C:$C,$E8) -> 19 | I8: 7 | J8: =IF(I8=0,(10-F8),I8-F8) -> 2 | K8: =IF(VLOOKUP($C8,Players!$C:$D,2,0)>H8,"YES",IF(VLOOKUP($C8,Players!$C:$D,2,0)=H8,"YES","NO")) -> YES | L8: =IF(VLOOKUP($C8,Players!$C:$D,2,0)>17,"NO",IF(VLOOKUP($C8,Players!$C:$D,2,0)<G8,"YES","NO")) -> NO | M8: =IFERROR(IF(I8="","",IF(VLOOKUP($C8,Players!$C:$D,2,0)>18,IF(K8="NO",IF(J8>2,0,3-J8),IF(J8>3,0,4-J8)),IF(L8="NO",IF(J8>2,0,3-J8),IF(J8>1,0,2-J8)))),0) -> 2 | N8: =IF(I8="","",IF(M8>3,"YES","NO")) -> NO | O8: =IF(E8>12,"YES","NO") -> NO | Q8: =SUM(M:M) -> 28 | S8: =IF(K8="YES",1,0) -> 1 | T8: =IF(L8="YES",1,0) -> 0 | U8: =IF(I8="","",I8-1-S8+T8) -> 5
A9: =A8 -> 1 | B9: =$B$2 -> Worrigee | C9: =C8 -> Brendan Oakes | D9: FRONT | E9: 8 | F9: =SUMIFS('Course Info'!$D:$D,'Course Info'!$B:$B,$B9,'Course Info'!$C:$C,$E9) -> 3 | G9: =SUMIFS('Course Info'!$E:$E,'Course Info'!$B:$B,$B9,'Course Info'!$C:$C,$E9) -> 8 | H9: =SUMIFS('Course Info'!$F:$F,'Course Info'!$B:$B,$B9,'Course Info'!$C:$C,$E9) -> 31 | I9: 4 | J9: =IF(I9=0,(10-F9),I9-F9) -> 1 | K9: =IF(VLOOKUP($C9,Players!$C:$D,2,0)>H9,"YES",IF(VLOOKUP($C9,Players!$C:$D,2,0)=H9,"YES","NO")) -> NO | L9: =IF(VLOOKUP($C9,Players!$C:$D,2,0)>17,"NO",IF(VLOOKUP($C9,Players!$C:$D,2,0)<G9,"YES","NO")) -> NO | M9: =IFERROR(IF(I9="","",IF(VLOOKUP($C9,Players!$C:$D,2,0)>18,IF(K9="NO",IF(J9>2,0,3-J9),IF(J9>3,0,4-J9)),IF(L9="NO",IF(J9>2,0,3-J9),IF(J9>1,0,2-J9)))),0) -> 2 | N9: =IF(I9="","",IF(M9>3,"YES","NO")) -> NO | O9: =IF(E9>12,"YES","NO") -> NO | Q9: =SUM(M:M) -> 28 | S9: =IF(K9="YES",1,0) -> 0 | T9: =IF(L9="YES",1,0) -> 0 | U9: =IF(I9="","",I9-1-S9+T9) -> 3
A10: =A9 -> 1 | B10: =$B$2 -> Worrigee | C10: =C9 -> Brendan Oakes | D10: FRONT | E10: 9 | F10: =SUMIFS('Course Info'!$D:$D,'Course Info'!$B:$B,$B10,'Course Info'!$C:$C,$E10) -> 4 | G10: =SUMIFS('Course Info'!$E:$E,'Course Info'!$B:$B,$B10,'Course Info'!$C:$C,$E10) -> 4 | H10: =SUMIFS('Course Info'!$F:$F,'Course Info'!$B:$B,$B10,'Course Info'!$C:$C,$E10) -> 20 | I10: 7 | J10: =IF(I10=0,(10-F10),I10-F10) -> 3 | K10: =IF(VLOOKUP($C10,Players!$C:$D,2,0)>H10,"YES",IF(VLOOKUP($C10,Players!$C:$D,2,0)=H10,"YES","NO")) -> YES | L10: =IF(VLOOKUP($C10,Players!$C:$D,2,0)>17,"NO",IF(VLOOKUP($C10,Players!$C:$D,2,0)<G10,"YES","NO")) -> NO | M10: =IFERROR(IF(I10="","",IF(VLOOKUP($C10,Players!$C:$D,2,0)>18,IF(K10="NO",IF(J10>2,0,3-J10),IF(J10>3,0,4-J10)),IF(L10="NO",IF(J10>2,0,3-J10),IF(J10>1,0,2-J10)))),0) -> 1 | N10: =IF(I10="","",IF(M10>3,"YES","NO")) -> NO | O10: =IF(E10>12,"YES","NO") -> NO | Q10: =SUM(M:M) -> 28 | S10: =IF(K10="YES",1,0) -> 1 | T10: =IF(L10="YES",1,0) -> 0 | U10: =IF(I10="","",I10-1-S10+T10) -> 5
A11: =A10 -> 1 | B11: =$B$2 -> Worrigee | C11: =C10 -> Brendan Oakes | D11: BACK | E11: 10 | F11: =SUMIFS('Course Info'!$D:$D,'Course Info'!$B:$B,$B11,'Course Info'!$C:$C,$E11) -> 4 | G11: =SUMIFS('Course Info'!$E:$E,'Course Info'!$B:$B,$B11,'Course Info'!$C:$C,$E11) -> 7 | H11: =SUMIFS('Course Info'!$F:$F,'Course Info'!$B:$B,$B11,'Course Info'!$C:$C,$E11) -> 22 | I11: 6 | J11: =IF(I11=0,(10-F11),I11-F11) -> 2 | K11: =IF(VLOOKUP($C11,Players!$C:$D,2,0)>H11,"YES",IF(VLOOKUP($C11,Players!$C:$D,2,0)=H11,"YES","NO")) -> NO | L11: =IF(VLOOKUP($C11,Players!$C:$D,2,0)>17,"NO",IF(VLOOKUP($C11,Players!$C:$D,2,0)<G11,"YES","NO")) -> NO | M11: =IFERROR(IF(I11="","",IF(VLOOKUP($C11,Players!$C:$D,2,0)>18,IF(K11="NO",IF(J11>2,0,3-J11),IF(J11>3,0,4-J11)),IF(L11="NO",IF(J11>2,0,3-J11),IF(J11>1,0,2-J11)))),0) -> 1 | N11: =IF(I11="","",IF(M11>3,"YES","NO")) -> NO | O11: =IF(E11>12,"YES","NO") -> NO | Q11: =SUM(M:M) -> 28 | S11: =IF(K11="YES",1,0) -> 0 | T11: =IF(L11="YES",1,0) -> 0 | U11: =IF(I11="","",I11-1-S11+T11) -> 5
A12: =A11 -> 1 | B12: =$B$2 -> Worrigee | C12: =C11 -> Brendan Oakes | D12: BACK | E12: 11 | F12: =SUMIFS('Course Info'!$D:$D,'Course Info'!$B:$B,$B12,'Course Info'!$C:$C,$E12) -> 5 | G12: =SUMIFS('Course Info'!$E:$E,'Course Info'!$B:$B,$B12,'Course Info'!$C:$C,$E12) -> 11 | H12: =SUMIFS('Course Info'!$F:$F,'Course Info'!$B:$B,$B12,'Course Info'!$C:$C,$E12) -> 30 | I12: 5 | J12: =IF(I12=0,(10-F12),I12-F12) -> 0 | K12: =IF(VLOOKUP($C12,Players!$C:$D,2,0)>H12,"YES",IF(VLOOKUP($C12,Players!$C:$D,2,0)=H12,"YES","NO")) -> NO | L12: =IF(VLOOKUP($C12,Players!$C:$D,2,0)>17,"NO",IF(VLOOKUP($C12,Players!$C:$D,2,0)<G12,"YES","NO")) -> NO | M12: =IFERROR(IF(I12="","",IF(VLOOKUP($C12,Players!$C:$D,2,0)>18,IF(K12="NO",IF(J12>2,0,3-J12),IF(J12>3,0,4-J12)),IF(L12="NO",IF(J12>2,0,3-J12),IF(J12>1,0,2-J12)))),0) -> 3 | N12: =IF(I12="","",IF(M12>3,"YES","NO")) -> NO | O12: =IF(E12>12,"YES","NO") -> NO | Q12: =SUM(M:M) -> 28 | S12: =IF(K12="YES",1,0) -> 0 | T12: =IF(L12="YES",1,0) -> 0 | U12: =IF(I12="","",I12-1-S12+T12) -> 4
A13: =A12 -> 1 | B13: =$B$2 -> Worrigee | C13: =C12 -> Brendan Oakes | D13: BACK | E13: 12 | F13: =SUMIFS('Course Info'!$D:$D,'Course Info'!$B:$B,$B13,'Course Info'!$C:$C,$E13) -> 3 | G13: =SUMIFS('Course Info'!$E:$E,'Course Info'!$B:$B,$B13,'Course Info'!$C:$C,$E13) -> 2 | H13: =SUMIFS('Course Info'!$F:$F,'Course Info'!$B:$B,$B13,'Course Info'!$C:$C,$E13) -> 27 | I13: 9 | J13: =IF(I13=0,(10-F13),I13-F13) -> 6 | K13: =IF(VLOOKUP($C13,Players!$C:$D,2,0)>H13,"YES",IF(VLOOKUP($C13,Players!$C:$D,2,0)=H13,"YES","NO")) -> NO | L13: =IF(VLOOKUP($C13,Players!$C:$D,2,0)>17,"NO",IF(VLOOKUP($C13,Players!$C:$D,2,0)<G13,"YES","NO")) -> NO | M13: =IFERROR(IF(I13="","",IF(VLOOKUP($C13,Players!$C:$D,2,0)>18,IF(K13="NO",IF(J13>2,0,3-J13),IF(J13>3,0,4-J13)),IF(L13="NO",IF(J13>2,0,3-J13),IF(J13>1,0,2-J13)))),0) -> 0 | N13: =IF(I13="","",IF(M13>3,"YES","NO")) -> NO | O13: =IF(E13>12,"YES","NO") -> NO | Q13: =SUM(M:M) -> 28 | S13: =IF(K13="YES",1,0) -> 0 | T13: =IF(L13="YES",1,0) -> 0 | U13: =IF(I13="","",I13-1-S13+T13) -> 8
A14: =A13 -> 1 | B14: =$B$2 -> Worrigee | C14: =C13 -> Brendan Oakes | D14: BACK | E14: 13 | F14: =SUMIFS('Course Info'!$D:$D,'Course Info'!$B:$B,$B14,'Course Info'!$C:$C,$E14) -> 4 | G14: =SUMIFS('Course Info'!$E:$E,'Course Info'!$B:$B,$B14,'Course Info'!$C:$C,$E14) -> 17 | H14: =SUMIFS('Course Info'!$F:$F,'Course Info'!$B:$B,$B14,'Course Info'!$C:$C,$E14) -> 33 | I14: 9 | J14: =IF(I14=0,(10-F14),I14-F14) -> 5 | K14: =IF(VLOOKUP($C14,Players!$C:$D,2,0)>H14,"YES",IF(VLOOKUP($C14,Players!$C:$D,2,0)=H14,"YES","NO")) -> NO | L14: =IF(VLOOKUP($C14,Players!$C:$D,2,0)>17,"NO",IF(VLOOKUP($C14,Players!$C:$D,2,0)<G14,"YES","NO")) -> NO | M14: =IFERROR(IF(I14="","",IF(VLOOKUP($C14,Players!$C:$D,2,0)>18,IF(K14="NO",IF(J14>2,0,3-J14),IF(J14>3,0,4-J14)),IF(L14="NO",IF(J14>2,0,3-J14),IF(J14>1,0,2-J14)))),0) -> 0 | N14: =IF(I14="","",IF(M14>3,"YES","NO")) -> NO | O14: =IF(E14>12,"YES","NO") -> YES | Q14: =SUM(M:M) -> 28 | S14: =IF(K14="YES",1,0) -> 0 | T14: =IF(L14="YES",1,0) -> 0 | U14: =IF(I14="","",I14-1-S14+T14) -> 8
... A18: =A17 -> 1 | B18: =$B$2 -> Worrigee | C18: =C17 -> Brendan Oakes | D18: BACK | E18: 17 | F18: =SUMIFS('Course Info'!$D:$D,'Course Info'!$B:$B,$B18,'Course Info'!$C:$C,$E18) -> 3 | G18: =SUMIFS('Course Info'!$E:$E,'Course Info'!$B:$B,$B18,'Course Info'!$C:$C,$E18) -> 13 | H18: =SUMIFS('Course Info'!$F:$F,'Course Info'!$B:$B,$B18,'Course Info'!$C:$C,$E18) -> 35 | I18: 9 | J18: =IF(I18=0,(10-F18),I18-F18) -> 6 | K18: =IF(VLOOKUP($C18,Players!$C:$D,2,0)>H18,"YES",IF(VLOOKUP($C18,Players!$C:$D,2,0)=H18,"YES","NO")) -> NO | L18: =IF(VLOOKUP($C18,Players!$C:$D,2,0)>17,"NO",IF(VLOOKUP($C18,Players!$C:$D,2,0)<G18,"YES","NO")) -> NO | M18: =IFERROR(IF(I18="","",IF(VLOOKUP($C18,Players!$C:$D,2,0)>18,IF(K18="NO",IF(J18>2,0,3-J18),IF(J18>3,0,4-J18)),IF(L18="NO",IF(J18>2,0,3-J18),IF(J18>1,0,2-J18)))),0) -> 0 | N18: =IF(I18="","",IF(M18>3,"YES","NO")) -> NO | O18: =IF(E18>12,"YES","NO") -> YES | Q18: =SUM(M:M) -> 28 | S18: =IF(K18="YES",1,0) -> 0 | T18: =IF(L18="YES",1,0) -> 0 | U18: =IF(I18="","",I18-1-S18+T18) -> 8
A19: =A18 -> 1 | B19: =$B$2 -> Worrigee | C19: =C18 -> Brendan Oakes | D19: BACK | E19: 18 | F19: =SUMIFS('Course Info'!$D:$D,'Course Info'!$B:$B,$B19,'Course Info'!$C:$C,$E19) -> 5 | G19: =SUMIFS('Course Info'!$E:$E,'Course Info'!$B:$B,$B19,'Course Info'!$C:$C,$E19) -> 14 | H19: =SUMIFS('Course Info'!$F:$F,'Course Info'!$B:$B,$B19,'Course Info'!$C:$C,$E19) -> 28 | I19: 6 | J19: =IF(I19=0,(10-F19),I19-F19) -> 1 | K19: =IF(VLOOKUP($C19,Players!$C:$D,2,0)>H19,"YES",IF(VLOOKUP($C19,Players!$C:$D,2,0)=H19,"YES","NO")) -> NO | L19: =IF(VLOOKUP($C19,Players!$C:$D,2,0)>17,"NO",IF(VLOOKUP($C19,Players!$C:$D,2,0)<G19,"YES","NO")) -> NO | M19: =IFERROR(IF(I19="","",IF(VLOOKUP($C19,Players!$C:$D,2,0)>18,IF(K19="NO",IF(J19>2,0,3-J19),IF(J19>3,0,4-J19)),IF(L19="NO",IF(J19>2,0,3-J19),IF(J19>1,0,2-J19)))),0) -> 2 | N19: =IF(I19="","",IF(M19>3,"YES","NO")) -> NO | O19: =IF(E19>12,"YES","NO") -> YES | P19: =SUM(I2:I19) -> 108 | Q19: =SUM(M:M) -> 28 | R19: =VLOOKUP(C19,Players!$C:$D,2,0) -> 20 | S19: =IF(K19="YES",1,0) -> 0 | T19: =IF(L19="YES",1,0) -> 0 | U19: =IF(I19="","",I19-1-S19+T19) -> 5 | V19: =RANK(Q19,$Q$2:$Q$19,0) -> 1

Sheet Andrew Murray
A1: LOOKUP | B1: COURSE | C1: PLAYER | D1: CATEGORY | E1: HOLE | F1: PAR | G1: INDEX 1 | H1: INDEX 2 | I1: SCORE | J1: OVER | K1: DOUBLE | L1: NO SHOT | M1: POINTS | N1: 4 OR 5 POINTER? | O1: LAST 6 | P1: ACC SCORE | Q1: ACC STAB | R1: HANDICAP | S1: DOUBLE? | T1: NO SHOT? | U1: NETT | V1: RANK
A2: 1 | B2: Worrigee | C2: =Players!C4 -> Andrew Murray | D2: FRONT | E2: 1 | F2: =SUMIFS('Course Info'!$D:$D,'Course Info'!$B:$B,$B2,'Course Info'!$C:$C,$E2) -> 5 | G2: =SUMIFS('Course Info'!$E:$E,'Course Info'!$B:$B,$B2,'Course Info'!$C:$C,$E2) -> 10 | H2: =SUMIFS('Course Info'!$F:$F,'Course Info'!$B:$B,$B2,'Course Info'!$C:$C,$E2) -> 23 | I2: 5 | J2: =IF(I2=0,(10-F2),I2-F2) -> 0 | K2: =IF(VLOOKUP($C2,Players!$C:$D,2,0)>H2,"YES",IF(VLOOKUP($C2,Players!$C:$D,2,0)=H2,"YES","NO")) -> NO | L2: =IF(VLOOKUP($C2,Players!$C:$D,2,0)>17,"NO",IF(VLOOKUP($C2,Players!$C:$D,2,0)<G2,"YES","NO")) -> NO | M2: =IFERROR(IF(I2="","",IF(VLOOKUP($C2,Players!$C:$D,2,0)>18,IF(K2="NO",IF(J2>2,0,3-J2),IF(J2>3,0,4-J2)),IF(L2="NO",IF(J2>2,0,3-J2),IF(J2>1,0,2-J2)))),0) -> 3 | N2: =IF(I2="","",IF(M2>3,"YES","NO")) -> NO | O2: =IF(E2>12,"YES","NO") -> NO | Q2: =SUM(M:M) -> 41 | S2: =IF(K2="YES",1,0) -> 0 | T2: =IF(L2="YES",1,0) -> 0 | U2: =IF(I2="","",I2-1-S2+T2) -> 4
A3: =A2 -> 1 | B3: =$B$2 -> Worrigee | C3: =C2 -> Andrew Murray | D3: FRONT | E3: 2 | F3: =SUMIFS('Course Info'!$D:$D,'Course Info'!$B:$B,$B3,'Course Info'!$C:$C,$E3) -> 3 | G3: =SUMIFS('Course Info'!$E:$E,'Course Info'!$B:$B,$B3,'Course Info'!$C:$C,$E3) -> 1 | H3: =SUMIFS('Course Info'!$F:$F,'Course Info'!$B:$B,$B3,'Course Info'!$C:$C,$E3) -> 26 | I3: 9 | J3: =IF(I3=0,(10-F3),I3-F3) -> 6 | K3: =IF(VLOOKUP($C3,Players!$C:$D,2,0)>H3,"YES",IF(VLOOKUP($C3,Players!$C:$D,2,0)=H3,"YES","NO")) -> NO | L3: =IF(VLOOKUP($C3,Players!$C:$D,2,0)>17,"NO",IF(VLOOKUP($C3,Players!$C:$D,2,0)<G3,"YES","NO")) -> NO | M3: =IFERROR(IF(I3="","",IF(VLOOKUP($C3,Players!$C:$D,2,0)>18,IF(K3="NO",IF(J3>2,0,3-J3),IF(J3>3,0,4-J3)),IF(L3="NO",IF(J3>2,0,3-J3),IF(J3>1,0,2-J3)))),0) -> 0 | N3: =IF(I3="","",IF(M3>3,"YES","NO")) -> NO | O3: =IF(E3>12,"YES","NO") -> NO | Q3: =SUM(M:M) -> 41 | S3: =IF(K3="YES",1,0) -> 0 | T3: =IF(L3="YES",1,0) -> 0 | U3: =IF(I3="","",I3-1-S3+T3) -> 8
A4: =A3 -> 1 | B4: =$B$2 -> Worrigee | C4: =C3 -> Andrew Murray | D4: FRONT | E4: 3 | F4: =SUMIFS('Course Info'!$D:$D,'Course Info'!$B:$B,$B4,'Course Info'!$C:$C,$E4) -> 4 | G4: =SUMIFS('Course Info'!$E:$E,'Course Info'!$B:$B,$B4,'Course Info'!$C:$C,$E4) -> 12 | H4: =SUMIFS('Course Info'!$F:$F,'Course Info'!$B:$B,$B4,'Course Info'!$C:$C,$E4) -> 29 | I4: 4 | J4: =IF(I4=0,(10-F4),I4-F4) -> 0 | K4: =IF(VLOOKUP($C4,Players!$C:$D,2,0)>H4,"YES",IF(VLOOKUP($C4,Players!$C:$D,2,0)=H4,"YES","NO")) -> NO | L4: =IF(VLOOKUP($C4,Players!$C:$D,2,0)>17,"NO",IF(VLOOKUP($C4,Players!$C:$D,2,0)<G4,"YES","NO")) -> NO | M4: =IFERROR(IF(I4="","",IF(VLOOKUP($C4,Players!$C:$D,2,0)>18,IF(K4="NO",IF(J4>2,0,3-J4),IF(J4>3,0,4-J4)),IF(L4="NO",IF(J4>2,0,3-J4),IF(J4>1,0,2-J4)))),0) -> 3 | N4: =IF(I4="","",IF(M4>3,"YES","NO")) -> NO | O4: =IF(E4>12,"YES","NO") -> NO | Q4: =SUM(M:M) -> 41 | S4: =IF(K4="YES",1,0) -> 0 | T4: =IF(L4="YES",1,0) -> 0 | U4: =IF(I4="","",I4-1-S4+T4) -> 3
A5: =A4 -> 1 | B5: =$B$2 -> Worrigee | C5: =C4 -> Andrew Murray | D5: FRONT | E5: 4 | F5: =SUMIFS('Course Info'!$D:$D,'Course Info'!$B:$B,$B5,'Course Info'!$C:$C,$E5) -> 4 | G5: =SUMIFS('Course Info'!$E:$E,'Course Info'!$B:$B,$B5,'Course Info'!$C:$C,$E5) -> 16 | H5: =SUMIFS('Course Info'!$F:$F,'Course Info'!$B:$B,$B5,'Course Info'!$C:$C,$E5) -> 32 | I5: 4 | J5: =IF(I5=0,(10-F5),I5-F5) -> 0 | K5: =IF(VLOOKUP($C5,Players!$C:$D,2,0)>H5,"YES",IF(VLOOKUP($C5,Players!$C:$D,2,0)=H5,"YES","NO")) -> NO | L5: =IF(VLOOKUP($C5,Players!$C:$D,2,0)>17,"NO",IF(VLOOKUP($C5,Players!$C:$D,2,0)<G5,"YES","NO")) -> NO | M5: =IFERROR(IF(I5="","",IF(VLOOKUP($C5,Players!$C:$D,2,0)>18,IF(K5="NO",IF(J5>2,0,3-J5),IF(J5>3,0,4-J5)),IF(L5="NO",IF(J5>2,0,3-J5),IF(J5>1,0,2-J5)))),0) -> 3 | N5: =IF(I5="","",IF(M5>3,"YES","NO")) -> NO | O5: =IF(E5>12,"YES","NO") -> NO | Q5: =SUM(M:M) -> 41 | S5: =IF(K5="YES",1,0) -> 0 | T5: =IF(L5="YES",1,0) -> 0 | U5: =IF(I5="","",I5-1-S5+T5) -> 3
A6: =A5 -> 1 | B6: =$B$2 -> Worrigee | C6: =C5 -> Andrew Murray | D6: FRONT | E6: 5 | F6: =SUMIFS('Course Info'!$D:$D,'Course Info'!$B:$B,$B6,'Course Info'!$C:$C,$E6) -> 4 | G6: =SUMIFS('Course Info'!$E:$E,'Course Info'!$B:$B,$B6,'Course Info'!$C:$C,$E6) -> 3 | H6: =SUMIFS('Course Info'!$F:$F,'Course Info'!$B:$B,$B6,'Course Info'!$C:$C,$E6) -> 21 | I6: 9 | J6: =IF(I6=0,(10-F6),I6-F6) -> 5 | K6: =IF(VLOOKUP($C6,Players!$C:$D,2,0)>H6,"YES",IF(VLOOKUP($C6,Players!$C:$D,2,0)=H6,"YES","NO")) -> NO | L6: =IF(VLOOKUP($C6,Players!$C:$D,2,0)>17,"NO",IF(VLOOKUP($C6,Players!$C:$D,2,0)<G6,"YES","NO")) -> NO | M6: =IFERROR(IF(I6="","",IF(VLOOKUP($C6,Players!$C:$D,2,0)>18,IF(K6="NO",IF(J6>2,0,3-J6),IF(J6>3,0,4-J6)),IF(L6="NO",IF(J6>2,0,3-J6),IF(J6>1,0,2-J6)))),0) -> 0 | N6: =IF(I6="","",IF(M6>3,"YES","NO")) -> NO | O6: =IF(E6>12,"YES","NO") -> NO | Q6: =SUM(M:M) -> 41 | S6: =IF(K6="YES",1,0) -> 0 | T6: =IF(L6="YES",1,0) -> 0 | U6: =IF(I6="","",I6-1-S6+T6) -> 8
A7: =A6 -> 1 | B7: =$B$2 -> Worrigee | C7: =C6 -> Andrew Murray | D7: FRONT | E7: 6 | F7: =SUMIFS('Course Info'!$D:$D,'Course Info'!$B:$B,$B7,'Course Info'!$C:$C,$E7) -> 3 | G7: =SUMIFS('Course Info'!$E:$E,'Course Info'!$B:$B,$B7,'Course Info'!$C:$C,$E7) -> 15 | H7: =SUMIFS('Course Info'!$F:$F,'Course Info'!$B:$B,$B7,'Course Info'!$C:$C,$E7) -> 36 | I7: 4 | J7: =IF(I7=0,(10-F7),I7-F7) -> 1 | K7: =IF(VLOOKUP($C7,Players!$C:$D,2,0)>H7,"YES",IF(VLOOKUP($C7,Players!$C:$D,2,0)=H7,"YES","NO")) -> NO | L7: =IF(VLOOKUP($C7,Players!$C:$D,2,0)>17,"NO",IF(VLOOKUP($C7,Players!$C:$D,2,0)<G7,"YES","NO")) -> NO | M7: =IFERROR(IF(I7="","",IF(VLOOKUP($C7,Players!$C:$D,2,0)>18,IF(K7="NO",IF(J7>2,0,3-J7),IF(J7>3,0,4-J7)),IF(L7="NO",IF(J7>2,0,3-J7),IF(J7>1,0,2-J7)))),0) -> 2 | N7: =IF(I7="","",IF(M7>3,"YES","NO")) -> NO | O7: =IF(E7>12,"YES","NO") -> NO | Q7: =SUM(M:M) -> 41 | S7: =IF(K7="YES",1,0) -> 0 | T7: =IF(L7="YES",1,0) -> 0 | U7: =IF(I7="","",I7-1-S7+T7) -> 3
A8: =A7 -> 1 | B8: =$B$2 -> Worrigee | C8: =C7 -> Andrew Murray | D8: FRONT | E8: 7 | F8: =SUMIFS('Course Info'!$D:$D,'Course Info'!$B:$B,$B8,'Course Info'!$C:$C,$E8) -> 5 | G8: =SUMIFS('Course Info'!$E:$E,'Course Info'!$B:$B,$B8,'Course Info'!$C:$C,$E8) -> 6 | H8: =SUMIFS('Course Info'!$F:$F,'Course Info'!$B:$B,$B8,'Course Info'!$C:$C,$E8) -> 19 | I8: 6 | J8: =IF(I8=0,(10-F8),I8-F8) -> 1 | K8: =IF(VLOOKUP($C8,Players!$C:$D,2,0)>H8,"YES",IF(VLOOKUP($C8,Players!$C:$D,2,0)=H8,"YES","NO")) -> YES | L8: =IF(VLOOKUP($C8,Players!$C:$D,2,0)>17,"NO",IF(VLOOKUP($C8,Players!$C:$D,2,0)<G8,"YES","NO")) -> NO | M8: =IFERROR(IF(I8="","",IF(VLOOKUP($C8,Players!$C:$D,2,0)>18,IF(K8="NO",IF(J8>2,0,3-J8),IF(J8>3,0,4-J8)),IF(L8="NO",IF(J8>2,0,3-J8),IF(J8>1,0,2-J8)))),0) -> 3 | N8: =IF(I8="","",IF(M8>3,"YES","NO")) -> NO | O8: =IF(E8>12,"YES","NO") -> NO | Q8: =SUM(M:M) -> 41 | S8: =IF(K8="YES",1,0) -> 1 | T8: =IF(L8="YES",1,0) -> 0 | U8: =IF(I8="","",I8-1-S8+T8) -> 4
A9: =A8 -> 1 | B9: =$B$2 -> Worrigee | C9: =C8 -> Andrew Murray | D9: FRONT | E9: 8 | F9: =SUMIFS('Course Info'!$D:$D,'Course Info'!$B:$B,$B9,'Course Info'!$C:$C,$E9) -> 3 | G9: =SUMIFS('Course Info'!$E:$E,'Course Info'!$B:$B,$B9,'Course Info'!$C:$C,$E9) -> 8 | H9: =SUMIFS('Course Info'!$F:$F,'Course Info'!$B:$B,$B9,'Course Info'!$C:$C,$E9) -> 31 | I9: 4 | J9: =IF(I9=0,(10-F9),I9-F9) -> 1 | K9: =IF(VLOOKUP($C9,Players!$C:$D,2,0)>H9,"YES",IF(VLOOKUP($C9,Players!$C:$D,2,0)=H9,"YES","NO")) -> NO | L9: =IF(VLOOKUP($C9,Players!$C:$D,2,0)>17,"NO",IF(VLOOKUP($C9,Players!$C:$D,2,0)<G9,"YES","NO")) -> NO | M9: =IFERROR(IF(I9="","",IF(VLOOKUP($C9,Players!$C:$D,2,0)>18,IF(K9="NO",IF(J9>2,0,3-J9),IF(J9>3,0,4-J9)),IF(L9="NO",IF(J9>2,0,3-J9),IF(J9>1,0,2-J9)))),0) -> 2 | N9: =IF(I9="","",IF(M9>3,"YES","NO")) -> NO | O9: =IF(E9>12,"YES","NO") -> NO | Q9: =SUM(M:M) -> 41 | S9: =IF(K9="YES",1,0) -> 0 | T9: =IF(L9="YES",1,0) -> 0 | U9: =IF(I9="","",I9-1-S9+T9) -> 3
A10: =A9 -> 1 | B10: =$B$2 -> Worrigee | C10: =C9 -> Andrew Murray | D10: FRONT | E10: 9 | F10: =SUMIFS('Course Info'!$D:$D,'Course Info'!$B:$B,$B10,'Course Info'!$C:$C,$E10) -> 4 | G10: =SUMIFS('Course Info'!$E:$E,'Course Info'!$B:$B,$B10,'Course Info'!$C:$C,$E10) -> 4 | H10: =SUMIFS('Course Info'!$F:$F,'Course Info'!$B:$B,$B10,'Course Info'!$C:$C,$E10) -> 20 | I10: 5 | J10: =IF(I10=0,(10-F10),I10-F10) -> 1 | K10: =IF(VLOOKUP($C10,Players!$C:$D,2,0)>H10,"YES",IF(VLOOKUP($C10,Players!$C:$D,2,0)=H10,"YES","NO")) -> YES | L10: =IF(VLOOKUP($C10,Players!$C:$D,2,0)>17,"NO",IF(VLOOKUP($C10,Players!$C:$D,2,0)<G10,"YES","NO")) -> NO | M10: =IFERROR(IF(I10="","",IF(VLOOKUP($C10,Players!$C:$D,2,0)>18,IF(K10="NO",IF(J10>2,0,3-J10),IF(J10>3,0,4-J10)),IF(L10="NO",IF(J10>2,0,3-J10),IF(J10>1,0,2-J10)))),0) -> 3 | N10: =IF(I10="","",IF(M10>3,"YES","NO")) -> NO | O10: =IF(E10>12,"YES","NO") -> NO | Q10: =SUM(M:M) -> 41 | S10: =IF(K10="YES",1,0) -> 1 | T10: =IF(L10="YES",1,0) -> 0 | U10: =IF(I10="","",I10-1-S10+T10) -> 3
A11: =A10 -> 1 | B11: =$B$2 -> Worrigee | C11: =C10 -> Andrew Murray | D11: BACK | E11: 10 | F11: =SUMIFS('Course Info'!$D:$D,'Course Info'!$B:$B,$B11,'Course Info'!$C:$C,$E11) -> 4 | G11: =SUMIFS('Course Info'!$E:$E,'Course Info'!$B:$B,$B11,'Course Info'!$C:$C,$E11) -> 7 | H11: =SUMIFS('Course Info'!$F:$F,'Course Info'!$B:$B,$B11,'Course Info'!$C:$C,$E11) -> 22 | I11: 4 | J11: =IF(I11=0,(10-F11),I11-F11) -> 0 | K11: =IF(VLOOKUP($C11,Players!$C:$D,2,0)>H11,"YES",IF(VLOOKUP($C11,Players!$C:$D,2,0)=H11,"YES","NO")) -> NO | L11: =IF(VLOOKUP($C11,Players!$C:$D,2,0)>17,"NO",IF(VLOOKUP($C11,Players!$C:$D,2,0)<G11,"YES","NO")) -> NO | M11: =IFERROR(IF(I11="","",IF(VLOOKUP($C11,Players!$C:$D,2,0)>18,IF(K11="NO",IF(J11>2,0,3-J11),IF(J11>3,0,4-J11)),IF(L11="NO",IF(J11>2,0,3-J11),IF(J11>1,0,2-J11)))),0) -> 3 | N11: =IF(I11="","",IF(M11>3,"YES","NO")) -> NO | O11: =IF(E11>12,"YES","NO") -> NO | Q11: =SUM(M:M) -> 41 | S11: =IF(K11="YES",1,0) -> 0 | T11: =IF(L11="YES",1,0) -> 0 | U11: =IF(I11="","",I11-1-S11+T11) -> 3
A12: =A11 -> 1 | B12: =$B$2 -> Worrigee | C12: =C11 -> Andrew Murray | D12: BACK | E12: 11 | F12: =SUMIFS('Course Info'!$D:$D,'Course Info'!$B:$B,$B12,'Course Info'!$C:$C,$E12) -> 5 | G12: =SUMIFS('Course Info'!$E:$E,'Course Info'!$B:$B,$B12,'Course Info'!$C:$C,$E12) -> 11 | H12: =SUMIFS('Course Info'!$F:$F,'Course Info'!$B:$B,$B12,'Course Info'!$C:$C,$E12) -> 30 | I12: 6 | J12: =IF(I12=0,(10-F12),I12-F12) -> 1 | K12: =IF(VLOOKUP($C12,Players!$C:$D,2,0)>H12,"YES",IF(VLOOKUP($C12,Players!$C:$D,2,0)=H12,"YES","NO")) -> NO | L12: =IF(VLOOKUP($C12,Players!$C:$D,2,0)>17,"NO",IF(VLOOKUP($C12,Players!$C:$D,2,0)<G12,"YES","NO")) -> NO | M12: =IFERROR(IF(I12="","",IF(VLOOKUP($C12,Players!$C:$D,2,0)>18,IF(K12="NO",IF(J12>2,0,3-J12),IF(J12>3,0,4-J12)),IF(L12="NO",IF(J12>2,0,3-J12),IF(J12>1,0,2-J12)))),0) -> 2 | N12: =IF(I12="","",IF(M12>3,"YES","NO")) -> NO | O12: =IF(E12>12,"YES","NO") -> NO | Q12: =SUM(M:M) -> 41 | S12: =IF(K12="YES",1,0) -> 0 | T12: =IF(L12="YES",1,0) -> 0 | U12: =IF(I12="","",I12-1-S12+T12) -> 5
A13: =A12 -> 1 | B13: =$B$2 -> Worrigee | C13: =C12 -> Andrew Murray | D13: BACK | E13: 12 | F13: =SUMIFS('Course Info'!$D:$D,'Course Info'!$B:$B,$B13,'Course Info'!$C:$C,$E13) -> 3 | G13: =SUMIFS('Course Info'!$E:$E,'Course Info'!$B:$B,$B13,'Course Info'!$C:$C,$E13) -> 2 | H13: =SUMIFS('Course Info'!$F:$F,'Course Info'!$B:$B,$B13,'Course Info'!$C:$C,$E13) -> 27 | I13: 3 | J13: =IF(I13=0,(10-F13),I13-F13) -> 0 | K13: =IF(VLOOKUP($C13,Players!$C:$D,2,0)>H13,"YES",IF(VLOOKUP($C13,Players!$C:$D,2,0)=H13,"YES","NO")) -> NO | L13: =IF(VLOOKUP($C13,Players!$C:$D,2,0)>17,"NO",IF(VLOOKUP($C13,Players!$C:$D,2,0)<G13,"YES","NO")) -> NO | M13: =IFERROR(IF(I13="","",IF(VLOOKUP($C13,Players!$C:$D,2,0)>18,IF(K13="NO",IF(J13>2,0,3-J13),IF(J13>3,0,4-J13)),IF(L13="NO",IF(J13>2,0,3-J13),IF(J13>1,0,2-J13)))),0) -> 3 | N13: =IF(I13="","",IF(M13>3,"YES","NO")) -> NO | O13: =IF(E13>12,"YES","NO") -> NO | Q13: =SUM(M:M) -> 41 | S13: =IF(K13="YES",1,0) -> 0 | T13: =IF(L13="YES",1,0) -> 0 | U13: =IF(I13="","",I13-1-S13+T13) -> 2
